setblock ~-7 ~4 ~13 minecraft:snow_block
setblock ~-7 ~8 ~7 minecraft:snow_block
setblock ~9 ~21 ~-4 minecraft:snow_block
setblock ~6 ~21 ~-8 minecraft:snow_block
setblock ~-2 ~7 ~22 minecraft:snow_block
setblock ~-8 ~9 ~6 minecraft:snow_block
setblock ~-7 ~23 ~7 minecraft:snow_block
setblock ~-5 ~25 ~-3 minecraft:snow_block
setblock ~3 ~9 ~19 minecraft:snow_block
setblock ~-7 ~21 ~-7 minecraft:snow_block
setblock ~3 ~5 ~19 minecraft:snow_block
setblock ~6 ~6 ~12 minecraft:snow_block
setblock ~-7 ~24 ~6 minecraft:snow_block
setblock ~-9 ~11 ~10 minecraft:snow_block
setblock ~-3 ~22 ~11 minecraft:snow_block
setblock ~-8 ~5 ~7 minecraft:snow_block
setblock ~-10 ~17 ~4 minecraft:snow_block
setblock ~7 ~14 ~12 minecraft:snow_block
setblock ~3 ~11 ~15 minecraft:snow_block
setblock ~-5 ~25 ~-4 minecraft:snow_block
setblock ~-10 ~21 ~-2 minecraft:snow_block
setblock ~3 ~25 ~-4 minecraft:snow_block
setblock ~-8 ~4 ~13 minecraft:snow_block
setblock ~9 ~18 ~-7 minecraft:snow_block
setblock ~-8 ~21 ~8 minecraft:snow_block
setblock ~-10 ~21 ~-1 minecraft:snow_block
setblock ~-8 ~8 ~4 minecraft:snow_block
setblock ~4 ~10 ~13 minecraft:blue_wool
setblock ~6 ~4 ~14 minecraft:snow_block
setblock ~-8 ~9 ~10 minecraft:snow_block
setblock ~-6 ~14 ~11 minecraft:snow_block
setblock ~-1 ~15 ~11 minecraft:snow_block
setblock ~-8 ~9 ~7 minecraft:snow_block
setblock ~-5 ~23 ~9 minecraft:snow_block
setblock ~-1 ~27 ~3 minecraft:snow_block
setblock ~3 ~0 ~-4 minecraft:snow_block
setblock ~-11 ~14 ~-6 minecraft:snow_block
setblock ~-4 ~15 ~12 minecraft:snow_block
setblock ~1 ~9 ~21 minecraft:snow_block
setblock ~-2 ~12 ~15 minecraft:snow_block
setblock ~1 ~13 ~-15 minecraft:snow_block
setblock ~1 ~8 ~21 minecraft:snow_block
setblock ~1 ~19 ~13 minecraft:snow_block
setblock ~-4 ~8 ~15 minecraft:snow_block
setblock ~1 ~15 ~15 minecraft:blue_wool
setblock ~-5 ~7 ~13 minecraft:snow_block
setblock ~0 ~23 ~-9 minecraft:snow_block
setblock ~3 ~8 ~19 minecraft:blue_wool
setblock ~9 ~21 ~4 minecraft:snow_block
setblock ~-6 ~23 ~8 minecraft:snow_block
setblock ~-7 ~6 ~9 minecraft:snow_block
setblock ~9 ~14 ~4 minecraft:snow_block
setblock ~-6 ~20 ~10 minecraft:snow_block
setblock ~-7 ~8 ~12 minecraft:snow_block
setblock ~-6 ~4 ~18 minecraft:snow_block
setblock ~-5 ~5 ~4 minecraft:snow_block
setblock ~-5 ~14 ~9 minecraft:snow_block
setblock ~9 ~10 ~-11 minecraft:snow_block
setblock ~-7 ~5 ~13 minecraft:snow_block
setblock ~-2 ~13 ~19 minecraft:snow_block
setblock ~3 ~7 ~16 minecraft:snow_block
setblock ~-7 ~5 ~7 minecraft:snow_block
setblock ~4 ~9 ~14 minecraft:snow_block
setblock ~-5 ~12 ~16 minecraft:snow_block
setblock ~-4 ~17 ~8 minecraft:snow_block
setblock ~-2 ~17 ~10 minecraft:snow_block
setblock ~-5 ~26 ~-2 minecraft:snow_block
setblock ~-2 ~6 ~-14 minecraft:snow_block
setblock ~-4 ~13 ~15 minecraft:snow_block
setblock ~-7 ~6 ~4 minecraft:snow_block
setblock ~8 ~7 ~-10 minecraft:snow_block
setblock ~-3 ~16 ~8 minecraft:snow_block
setblock ~-5 ~16 ~8 minecraft:snow_block
setblock ~-10 ~19 ~-5 minecraft:snow_block
setblock ~-2 ~2 ~-10 minecraft:snow_block
setblock ~5 ~9 ~13 minecraft:snow_block
setblock ~-8 ~11 ~13 minecraft:snow_block
setblock ~-3 ~27 ~4 minecraft:snow_block
setblock ~1 ~13 ~19 minecraft:snow_block
setblock ~-9 ~22 ~-2 minecraft:snow_block
setblock ~4 ~25 ~-4 minecraft:snow_block
setblock ~-3 ~10 ~12 minecraft:snow_block
setblock ~-5 ~17 ~14 minecraft:snow_block
setblock ~4 ~6 ~12 minecraft:snow_block
setblock ~-4 ~7 ~15 minecraft:snow_block
setblock ~0 ~8 ~19 minecraft:snow_block
setblock ~-4 ~13 ~-14 minecraft:snow_block
setblock ~-3 ~12 ~16 minecraft:snow_block
setblock ~0 ~13 ~19 minecraft:snow_block
setblock ~-6 ~5 ~18 minecraft:snow_block
setblock ~-8 ~8 ~-12 minecraft:snow_block
setblock ~-1 ~8 ~22 minecraft:snow_block
setblock ~-2 ~7 ~0 minecraft:snow_block
setblock ~0 ~23 ~-8 minecraft:snow_block
setblock ~-4 ~19 ~-11 minecraft:snow_block
setblock ~0 ~6 ~21 minecraft:snow_block
setblock ~9 ~7 ~-5 minecraft:snow_block
setblock ~6 ~6 ~13 minecraft:snow_block
setblock ~-7 ~7 ~8 minecraft:snow_block
setblock ~8 ~12 ~12 minecraft:snow_block
setblock ~-9 ~20 ~8 minecraft:snow_block
setblock ~-1 ~2 ~-10 minecraft:snow_block
setblock ~-2 ~9 ~-14 minecraft:snow_block
setblock ~-7 ~3 ~9 minecraft:snow_block
setblock ~-8 ~6 ~11 minecraft:snow_block
setblock ~-9 ~23 ~-2 minecraft:snow_block
setblock ~8 ~3 ~-7 minecraft:snow_block
setblock ~0 ~9 ~19 minecraft:snow_block
setblock ~4 ~7 ~20 minecraft:snow_block
setblock ~-10 ~10 ~6 minecraft:snow_block
setblock ~7 ~7 ~12 minecraft:snow_block
setblock ~-2 ~10 ~13 minecraft:snow_block
setblock ~-2 ~8 ~19 minecraft:snow_block
setblock ~-8 ~3 ~9 minecraft:snow_block
setblock ~10 ~8 ~-5 minecraft:snow_block
setblock ~9 ~14 ~10 minecraft:snow_block
setblock ~-8 ~4 ~-11 minecraft:snow_block
setblock ~-11 ~18 ~-1 minecraft:snow_block
setblock ~2 ~26 ~-2 minecraft:snow_block
setblock ~4 ~9 ~16 minecraft:snow_block
setblock ~-9 ~4 ~3 minecraft:snow_block
setblock ~4 ~9 ~6 minecraft:snow_block
setblock ~-1 ~7 ~22 minecraft:snow_block
setblock ~-7 ~9 ~9 minecraft:snow_block
setblock ~-3 ~8 ~17 minecraft:snow_block
setblock ~-7 ~5 ~-11 minecraft:snow_block
setblock ~7 ~8 ~5 minecraft:blue_wool
setblock ~-8 ~6 ~7 minecraft:snow_block
setblock ~-11 ~19 ~-4 minecraft:snow_block
setblock ~-1 ~12 ~19 minecraft:snow_block
setblock ~-6 ~3 ~13 minecraft:snow_block
setblock ~10 ~14 ~-3 minecraft:snow_block
setblock ~-10 ~13 ~-10 minecraft:snow_block
setblock ~7 ~12 ~13 minecraft:snow_block
setblock ~-5 ~0 ~-7 minecraft:snow_block
setblock ~-7 ~6 ~7 minecraft:snow_block
setblock ~7 ~6 ~7 minecraft:snow_block
setblock ~-1 ~24 ~-7 minecraft:snow_block
setblock ~6 ~7 ~6 minecraft:snow_block
setblock ~5 ~25 ~4 minecraft:snow_block
setblock ~-11 ~16 ~0 minecraft:snow_block
setblock ~5 ~8 ~17 minecraft:snow_block
setblock ~-11 ~13 ~2 minecraft:snow_block
setblock ~-1 ~17 ~-13 minecraft:snow_block
setblock ~0 ~7 ~22 minecraft:snow_block
setblock ~2 ~10 ~13 minecraft:snow_block
setblock ~5 ~13 ~13 minecraft:snow_block
setblock ~-2 ~20 ~11 minecraft:snow_block
setblock ~-5 ~8 ~15 minecraft:blue_wool
setblock ~8 ~2 ~-1 minecraft:snow_block
setblock ~-9 ~4 ~-8 minecraft:snow_block
setblock ~6 ~4 ~9 minecraft:snow_block
setblock ~-11 ~15 ~3 minecraft:snow_block
setblock ~-7 ~7 ~14 minecraft:snow_block
setblock ~5 ~22 ~10 minecraft:snow_block
setblock ~-6 ~7 ~10 minecraft:snow_block
setblock ~7 ~3 ~12 minecraft:snow_block
setblock ~8 ~11 ~10 minecraft:snow_block
setblock ~-5 ~25 ~-2 minecraft:snow_block
setblock ~7 ~24 ~0 minecraft:snow_block
setblock ~-3 ~3 ~2 minecraft:snow_block
setblock ~-8 ~24 ~4 minecraft:snow_block
setblock ~-9 ~16 ~-11 minecraft:snow_block
setblock ~-6 ~8 ~13 minecraft:blue_wool
setblock ~-7 ~3 ~15 minecraft:snow_block
setblock ~6 ~4 ~11 minecraft:snow_block
setblock ~-8 ~4 ~8 minecraft:snow_block
setblock ~-7 ~21 ~10 minecraft:snow_block
setblock ~-6 ~4 ~13 minecraft:snow_block
setblock ~-8 ~9 ~9 minecraft:snow_block
setblock ~7 ~20 ~-8 minecraft:snow_block
setblock ~6 ~5 ~15 minecraft:snow_block
setblock ~-3 ~8 ~20 minecraft:blue_wool
setblock ~-7 ~2 ~10 minecraft:snow_block
setblock ~-6 ~12 ~-14 minecraft:snow_block
setblock ~6 ~4 ~10 minecraft:snow_block
setblock ~2 ~8 ~19 minecraft:snow_block
setblock ~-11 ~11 ~9 minecraft:snow_block
setblock ~-10 ~14 ~10 minecraft:snow_block
setblock ~-6 ~8 ~17 minecraft:snow_block
setblock ~-10 ~14 ~5 minecraft:snow_block
setblock ~0 ~12 ~20 minecraft:snow_block
setblock ~-7 ~24 ~-2 minecraft:snow_block
setblock ~6 ~5 ~13 minecraft:snow_block
setblock ~1 ~18 ~11 minecraft:snow_block
setblock ~6 ~7 ~13 minecraft:snow_block
setblock ~-5 ~5 ~15 minecraft:snow_block
setblock ~6 ~25 ~0 minecraft:snow_block
setblock ~-7 ~21 ~-8 minecraft:snow_block
setblock ~-5 ~3 ~-11 minecraft:snow_block
setblock ~-2 ~14 ~18 minecraft:snow_block
setblock ~-7 ~4 ~15 minecraft:snow_block
setblock ~-9 ~22 ~3 minecraft:snow_block
setblock ~7 ~4 ~10 minecraft:snow_block
setblock ~-6 ~14 ~-13 minecraft:snow_block
setblock ~-3 ~7 ~19 minecraft:snow_block
setblock ~-5 ~1 ~-10 minecraft:snow_block
setblock ~-9 ~24 ~1 minecraft:snow_block
setblock ~-10 ~8 ~-10 minecraft:snow_block
setblock ~-6 ~5 ~11 minecraft:snow_block
setblock ~-5 ~6 ~15 minecraft:snow_block
setblock ~-4 ~10 ~18 minecraft:snow_block
setblock ~-7 ~13 ~-13 minecraft:snow_block
setblock ~9 ~3 ~-4 minecraft:snow_block
setblock ~-1 ~12 ~-15 minecraft:snow_block
setblock ~2 ~24 ~8 minecraft:snow_block
setblock ~-9 ~19 ~9 minecraft:snow_block
setblock ~3 ~27 ~2 minecraft:snow_block
setblock ~-3 ~10 ~19 minecraft:snow_block
setblock ~4 ~10 ~-14 minecraft:snow_block
setblock ~-6 ~18 ~9 minecraft:snow_block
setblock ~-7 ~4 ~14 minecraft:snow_block
setblock ~7 ~18 ~7 minecraft:snow_block
setblock ~-6 ~7 ~11 minecraft:snow_block
setblock ~-10 ~12 ~9 minecraft:blue_wool
setblock ~-5 ~5 ~17 minecraft:snow_block
setblock ~-2 ~7 ~20 minecraft:snow_block
setblock ~-5 ~6 ~18 minecraft:blue_wool
setblock ~-5 ~8 ~16 minecraft:snow_block
setblock ~-7 ~6 ~14 minecraft:snow_block
setblock ~-11 ~6 ~-2 minecraft:snow_block
setblock ~3 ~12 ~16 minecraft:snow_block
setblock ~-3 ~6 ~22 minecraft:snow_block
setblock ~-8 ~6 ~6 minecraft:snow_block
setblock ~0 ~3 ~-11 minecraft:snow_block
setblock ~-5 ~7 ~14 minecraft:snow_block
setblock ~-10 ~20 ~1 minecraft:snow_block
setblock ~-8 ~8 ~10 minecraft:snow_block
setblock ~7 ~15 ~-12 minecraft:snow_block
setblock ~-7 ~22 ~9 minecraft:snow_block
setblock ~-3 ~4 ~-13 minecraft:snow_block
setblock ~4 ~8 ~19 minecraft:snow_block
setblock ~0 ~25 ~-5 minecraft:snow_block
setblock ~4 ~11 ~-14 minecraft:snow_block
setblock ~6 ~3 ~14 minecraft:snow_block
setblock ~-1 ~26 ~8 minecraft:snow_block
setblock ~1 ~19 ~-12 minecraft:snow_block
setblock ~-8 ~5 ~12 minecraft:snow_block
setblock ~-10 ~22 ~4 minecraft:snow_block
setblock ~4 ~12 ~-14 minecraft:snow_block
setblock ~-9 ~15 ~5 minecraft:snow_block
setblock ~-1 ~11 ~13 minecraft:snow_block
setblock ~-2 ~4 ~-12 minecraft:snow_block
setblock ~6 ~3 ~3 minecraft:snow_block
setblock ~9 ~9 ~-10 minecraft:snow_block
setblock ~-7 ~25 ~4 minecraft:snow_block
setblock ~-6 ~6 ~17 minecraft:snow_block
setblock ~-3 ~21 ~-10 minecraft:snow_block
setblock ~0 ~9 ~-15 minecraft:snow_block
setblock ~-5 ~0 ~-6 minecraft:snow_block
setblock ~5 ~16 ~13 minecraft:snow_block
setblock ~1 ~23 ~-9 minecraft:snow_block
setblock ~7 ~22 ~7 minecraft:snow_block
setblock ~-5 ~11 ~17 minecraft:snow_block
setblock ~-11 ~18 ~-2 minecraft:snow_block
setblock ~3 ~7 ~13 minecraft:snow_block
setblock ~5 ~5 ~19 minecraft:snow_block
setblock ~-11 ~12 ~-7 minecraft:snow_block
setblock ~-10 ~19 ~1 minecraft:snow_block
setblock ~-5 ~8 ~19 minecraft:snow_block
setblock ~3 ~6 ~5 minecraft:snow_block
setblock ~5 ~22 ~-7 minecraft:snow_block
setblock ~10 ~17 ~-1 minecraft:snow_block
setblock ~3 ~24 ~-5 minecraft:snow_block
setblock ~-6 ~6 ~18 minecraft:snow_block
setblock ~-9 ~21 ~-4 minecraft:snow_block
setblock ~5 ~7 ~11 minecraft:snow_block
setblock ~0 ~8 ~22 minecraft:snow_block
setblock ~-10 ~10 ~-11 minecraft:snow_block
setblock ~-4 ~14 ~-14 minecraft:snow_block
setblock ~-7 ~19 ~10 minecraft:snow_block
setblock ~-5 ~7 ~18 minecraft:snow_block
setblock ~-6 ~5 ~12 minecraft:snow_block
setblock ~-1 ~26 ~5 minecraft:snow_block
setblock ~-3 ~8 ~21 minecraft:snow_block
setblock ~-4 ~7 ~20 minecraft:blue_wool
setblock ~-3 ~16 ~12 minecraft:snow_block
setblock ~-6 ~3 ~2 minecraft:snow_block
setblock ~-1 ~6 ~21 minecraft:snow_block
setblock ~10 ~18 ~-5 minecraft:snow_block
setblock ~-11 ~13 ~-5 minecraft:snow_block
setblock ~3 ~15 ~13 minecraft:snow_block
setblock ~6 ~8 ~14 minecraft:snow_block
setblock ~-6 ~0 ~-2 minecraft:snow_block
setblock ~-3 ~10 ~-15 minecraft:snow_block
setblock ~-1 ~14 ~14 minecraft:snow_block
setblock ~-7 ~3 ~12 minecraft:snow_block
setblock ~0 ~9 ~21 minecraft:snow_block
setblock ~-5 ~8 ~17 minecraft:snow_block
setblock ~-3 ~12 ~18 minecraft:blue_wool
setblock ~-2 ~11 ~14 minecraft:snow_block
setblock ~7 ~15 ~9 minecraft:snow_block
setblock ~-11 ~17 ~1 minecraft:snow_block
setblock ~6 ~18 ~8 minecraft:snow_block
setblock ~1 ~21 ~12 minecraft:snow_block
setblock ~0 ~14 ~18 minecraft:blue_wool
setblock ~-4 ~16 ~-13 minecraft:snow_block
setblock ~-10 ~11 ~-9 minecraft:snow_block
setblock ~1 ~16 ~13 minecraft:blue_wool
setblock ~-5 ~6 ~14 minecraft:snow_block
setblock ~-1 ~16 ~-14 minecraft:snow_block
setblock ~-8 ~10 ~-12 minecraft:snow_block
setblock ~0 ~10 ~19 minecraft:snow_block
setblock ~0 ~20 ~15 minecraft:snow_block
setblock ~-7 ~19 ~-9 minecraft:snow_block
setblock ~10 ~9 ~-3 minecraft:snow_block
setblock ~6 ~6 ~14 minecraft:snow_block
setblock ~7 ~21 ~-7 minecraft:snow_block
setblock ~-5 ~15 ~9 minecraft:snow_block
setblock ~7 ~7 ~9 minecraft:snow_block
setblock ~2 ~8 ~21 minecraft:snow_block
setblock ~5 ~8 ~11 minecraft:snow_block
setblock ~-5 ~18 ~8 minecraft:snow_block
setblock ~3 ~11 ~14 minecraft:snow_block
setblock ~9 ~21 ~3 minecraft:snow_block
setblock ~-2 ~23 ~-9 minecraft:snow_block
setblock ~-4 ~6 ~19 minecraft:snow_block
setblock ~-5 ~5 ~16 minecraft:snow_block
setblock ~3 ~17 ~-13 minecraft:snow_block
setblock ~-11 ~17 ~-6 minecraft:snow_block
setblock ~9 ~20 ~4 minecraft:snow_block
setblock ~-3 ~8 ~16 minecraft:snow_block
setblock ~2 ~17 ~11 minecraft:snow_block
setblock ~-6 ~14 ~12 minecraft:snow_block
setblock ~-8 ~4 ~11 minecraft:snow_block
setblock ~-9 ~5 ~2 minecraft:snow_block
setblock ~10 ~9 ~2 minecraft:snow_block
setblock ~1 ~20 ~-12 minecraft:snow_block
setblock ~-9 ~19 ~-7 minecraft:snow_block
setblock ~-5 ~6 ~19 minecraft:blue_wool
setblock ~-6 ~4 ~17 minecraft:snow_block
setblock ~-7 ~23 ~-4 minecraft:snow_block
setblock ~-3 ~7 ~-14 minecraft:snow_block
setblock ~-9 ~20 ~-7 minecraft:snow_block
setblock ~-1 ~7 ~3 minecraft:snow_block
setblock ~-8 ~14 ~12 minecraft:snow_block
setblock ~6 ~4 ~13 minecraft:snow_block
setblock ~-10 ~9 ~-9 minecraft:snow_block
setblock ~0 ~21 ~-10 minecraft:snow_block
setblock ~-7 ~2 ~11 minecraft:snow_block
setblock ~7 ~6 ~11 minecraft:snow_block
setblock ~-10 ~14 ~9 minecraft:snow_block
setblock ~-7 ~5 ~14 minecraft:snow_block
setblock ~6 ~3 ~1 minecraft:snow_block
setblock ~-7 ~25 ~1 minecraft:snow_block
setblock ~-8 ~7 ~10 minecraft:snow_block
setblock ~-10 ~19 ~-3 minecraft:snow_block
setblock ~2 ~9 ~17 minecraft:snow_block
setblock ~6 ~23 ~-4 minecraft:snow_block
setblock ~1 ~26 ~6 minecraft:snow_block
setblock ~7 ~7 ~11 minecraft:snow_block
setblock ~2 ~21 ~-10 minecraft:snow_block
setblock ~0 ~13 ~13 minecraft:snow_block
setblock ~-6 ~8 ~14 minecraft:snow_block
setblock ~3 ~8 ~13 minecraft:snow_block
setblock ~7 ~4 ~11 minecraft:snow_block
setblock ~-11 ~13 ~-8 minecraft:snow_block
setblock ~-4 ~6 ~5 minecraft:snow_block
setblock ~7 ~9 ~8 minecraft:snow_block
setblock ~-11 ~10 ~-7 minecraft:snow_block
setblock ~-1 ~26 ~6 minecraft:snow_block
setblock ~4 ~6 ~20 minecraft:snow_block
setblock ~2 ~16 ~12 minecraft:snow_block
setblock ~8 ~3 ~-6 minecraft:snow_block
setblock ~-6 ~4 ~12 minecraft:snow_block
setblock ~-2 ~24 ~-6 minecraft:snow_block
setblock ~6 ~5 ~7 minecraft:snow_block
setblock ~1 ~13 ~18 minecraft:blue_wool
setblock ~8 ~21 ~-6 minecraft:snow_block
setblock ~9 ~8 ~-5 minecraft:snow_block
setblock ~-10 ~20 ~2 minecraft:snow_block
setblock ~-7 ~6 ~12 minecraft:snow_block
setblock ~-7 ~5 ~8 minecraft:snow_block
setblock ~4 ~11 ~12 minecraft:snow_block
setblock ~-8 ~17 ~9 minecraft:snow_block
setblock ~6 ~9 ~-13 minecraft:snow_block
setblock ~-7 ~23 ~8 minecraft:snow_block
setblock ~7 ~10 ~8 minecraft:snow_block
setblock ~-5 ~4 ~17 minecraft:snow_block
setblock ~-3 ~1 ~-2 minecraft:snow_block
setblock ~7 ~25 ~1 minecraft:snow_block
setblock ~-9 ~22 ~0 minecraft:snow_block
setblock ~-8 ~4 ~9 minecraft:snow_block
setblock ~-9 ~9 ~-12 minecraft:snow_block
setblock ~9 ~9 ~-7 minecraft:snow_block
setblock ~-3 ~25 ~-4 minecraft:snow_block
setblock ~-1 ~17 ~-14 minecraft:snow_block
setblock ~6 ~4 ~16 minecraft:snow_block
setblock ~6 ~5 ~17 minecraft:snow_block
setblock ~5 ~8 ~14 minecraft:snow_block
setblock ~-2 ~25 ~9 minecraft:snow_block
setblock ~-7 ~10 ~10 minecraft:snow_block
setblock ~-5 ~19 ~9 minecraft:snow_block
setblock ~-10 ~17 ~5 minecraft:snow_block
setblock ~-3 ~9 ~15 minecraft:snow_block
setblock ~-3 ~6 ~-13 minecraft:snow_block
setblock ~3 ~6 ~20 minecraft:blue_wool
setblock ~2 ~26 ~-1 minecraft:snow_block
setblock ~7 ~23 ~4 minecraft:snow_block
setblock ~-1 ~1 ~-1 minecraft:snow_block
setblock ~9 ~17 ~-7 minecraft:snow_block
setblock ~-4 ~12 ~17 minecraft:snow_block
setblock ~6 ~8 ~12 minecraft:snow_block
setblock ~-8 ~6 ~8 minecraft:snow_block
setblock ~8 ~12 ~13 minecraft:snow_block
setblock ~3 ~8 ~-14 minecraft:snow_block
setblock ~6 ~7 ~12 minecraft:snow_block
setblock ~2 ~7 ~20 minecraft:blue_wool
setblock ~10 ~12 ~9 minecraft:snow_block
setblock ~1 ~25 ~7 minecraft:snow_block
setblock ~-10 ~20 ~0 minecraft:snow_block
setblock ~4 ~6 ~16 minecraft:snow_block
setblock ~6 ~19 ~-9 minecraft:snow_block
setblock ~5 ~5 ~18 minecraft:snow_block
setblock ~0 ~8 ~21 minecraft:blue_wool
setblock ~5 ~8 ~12 minecraft:snow_block
setblock ~-11 ~7 ~-1 minecraft:snow_block
setblock ~-3 ~4 ~3 minecraft:snow_block
setblock ~4 ~10 ~17 minecraft:snow_block
setblock ~1 ~2 ~-10 minecraft:snow_block
setblock ~-10 ~17 ~-7 minecraft:snow_block
setblock ~-5 ~26 ~2 minecraft:snow_block
setblock ~3 ~6 ~18 minecraft:snow_block
setblock ~-3 ~26 ~0 minecraft:snow_block
setblock ~-8 ~7 ~11 minecraft:snow_block
setblock ~5 ~11 ~12 minecraft:snow_block
setblock ~7 ~6 ~10 minecraft:snow_block
setblock ~-9 ~19 ~6 minecraft:snow_block
setblock ~-7 ~8 ~6 minecraft:snow_block
setblock ~-6 ~18 ~-11 minecraft:snow_block
setblock ~3 ~10 ~16 minecraft:blue_wool
setblock ~-1 ~1 ~-10 minecraft:snow_block
setblock ~2 ~7 ~21 minecraft:blue_wool
setblock ~1 ~15 ~14 minecraft:snow_block
setblock ~7 ~9 ~4 minecraft:snow_block
setblock ~-9 ~9 ~4 minecraft:snow_block
setblock ~-1 ~2 ~-1 minecraft:snow_block
setblock ~-10 ~17 ~-6 minecraft:snow_block
setblock ~0 ~12 ~19 minecraft:snow_block
setblock ~-2 ~20 ~13 minecraft:snow_block
setblock ~-3 ~9 ~18 minecraft:snow_block
setblock ~-1 ~24 ~10 minecraft:snow_block
setblock ~-6 ~6 ~10 minecraft:snow_block
setblock ~8 ~23 ~-1 minecraft:snow_block
setblock ~-4 ~24 ~9 minecraft:snow_block
setblock ~-7 ~8 ~10 minecraft:snow_block
setblock ~-4 ~2 ~-10 minecraft:snow_block
setblock ~-7 ~10 ~8 minecraft:snow_block
setblock ~-4 ~9 ~12 minecraft:snow_block
setblock ~-4 ~25 ~-4 minecraft:snow_block
setblock ~7 ~7 ~5 minecraft:snow_block
setblock ~6 ~3 ~16 minecraft:snow_block
setblock ~-3 ~6 ~20 minecraft:snow_block
setblock ~-1 ~8 ~-14 minecraft:snow_block
setblock ~6 ~8 ~5 minecraft:snow_block
setblock ~-9 ~11 ~5 minecraft:snow_block
setblock ~-7 ~20 ~10 minecraft:snow_block
setblock ~-8 ~6 ~10 minecraft:snow_block
setblock ~0 ~11 ~19 minecraft:snow_block
setblock ~-8 ~7 ~9 minecraft:snow_block
setblock ~2 ~9 ~7 minecraft:snow_block
setblock ~8 ~16 ~5 minecraft:snow_block
setblock ~-6 ~10 ~-14 minecraft:snow_block
setblock ~-4 ~11 ~15 minecraft:snow_block
setblock ~2 ~11 ~16 minecraft:snow_block
setblock ~8 ~10 ~-11 minecraft:snow_block
setblock ~-9 ~14 ~10 minecraft:snow_block
setblock ~-1 ~20 ~15 minecraft:snow_block
setblock ~-5 ~3 ~2 minecraft:snow_block
setblock ~4 ~2 ~-1 minecraft:snow_block
setblock ~1 ~8 ~19 minecraft:snow_block
setblock ~6 ~20 ~10 minecraft:snow_block
setblock ~9 ~20 ~-5 minecraft:snow_block
setblock ~-1 ~18 ~-13 minecraft:snow_block
setblock ~-3 ~16 ~11 minecraft:snow_block
setblock ~-10 ~19 ~3 minecraft:snow_block
setblock ~8 ~8 ~-11 minecraft:snow_block
setblock ~2 ~26 ~7 minecraft:snow_block
setblock ~5 ~5 ~16 minecraft:snow_block
setblock ~7 ~13 ~-13 minecraft:snow_block
setblock ~1 ~23 ~11 minecraft:snow_block
setblock ~3 ~7 ~19 minecraft:blue_wool
setblock ~2 ~8 ~20 minecraft:blue_wool
setblock ~9 ~13 ~4 minecraft:snow_block
setblock ~-11 ~11 ~1 minecraft:snow_block
setblock ~-11 ~15 ~1 minecraft:snow_block
setblock ~8 ~3 ~-9 minecraft:snow_block
setblock ~-5 ~12 ~-14 minecraft:snow_block
setblock ~-10 ~12 ~5 minecraft:snow_block
setblock ~-8 ~10 ~5 minecraft:snow_block
setblock ~-1 ~8 ~7 minecraft:snow_block
setblock ~-7 ~1 ~-9 minecraft:snow_block
setblock ~3 ~7 ~5 minecraft:snow_block
setblock ~-9 ~21 ~5 minecraft:snow_block
setblock ~-6 ~10 ~13 minecraft:snow_block
setblock ~-2 ~18 ~12 minecraft:snow_block
setblock ~6 ~0 ~-5 minecraft:snow_block
setblock ~0 ~8 ~20 minecraft:snow_block
setblock ~-11 ~9 ~-4 minecraft:snow_block
setblock ~-5 ~11 ~15 minecraft:snow_block
setblock ~3 ~16 ~8 minecraft:snow_block
setblock ~2 ~3 ~2 minecraft:snow_block
setblock ~6 ~6 ~7 minecraft:snow_block
setblock ~5 ~7 ~10 minecraft:snow_block
setblock ~-8 ~23 ~4 minecraft:snow_block
setblock ~3 ~19 ~-11 minecraft:snow_block
setblock ~-5 ~5 ~19 minecraft:snow_block
setblock ~-2 ~3 ~1 minecraft:snow_block
setblock ~0 ~24 ~-6 minecraft:snow_block
setblock ~-7 ~7 ~10 minecraft:snow_block
setblock ~-2 ~14 ~13 minecraft:snow_block
setblock ~6 ~4 ~8 minecraft:snow_block
setblock ~3 ~10 ~19 minecraft:snow_block
setblock ~6 ~22 ~9 minecraft:snow_block
setblock ~-1 ~24 ~-6 minecraft:snow_block
setblock ~2 ~13 ~17 minecraft:snow_block
setblock ~-5 ~5 ~12 minecraft:snow_block
setblock ~3 ~11 ~18 minecraft:snow_block
setblock ~-8 ~14 ~-12 minecraft:snow_block
setblock ~-8 ~16 ~-11 minecraft:snow_block
setblock ~6 ~5 ~9 minecraft:snow_block
setblock ~-5 ~23 ~8 minecraft:snow_block
setblock ~-3 ~10 ~14 minecraft:snow_block
setblock ~-7 ~17 ~-11 minecraft:snow_block
setblock ~-2 ~10 ~18 minecraft:snow_block
setblock ~2 ~23 ~-7 minecraft:snow_block
setblock ~5 ~4 ~12 minecraft:snow_block
setblock ~6 ~2 ~10 minecraft:snow_block
setblock ~-4 ~14 ~10 minecraft:snow_block
setblock ~-7 ~4 ~11 minecraft:snow_block
setblock ~10 ~16 ~-1 minecraft:snow_block
setblock ~0 ~2 ~0 minecraft:snow_block
setblock ~2 ~17 ~-13 minecraft:snow_block
setblock ~-10 ~20 ~3 minecraft:snow_block
setblock ~-2 ~7 ~21 minecraft:blue_wool
setblock ~-9 ~15 ~10 minecraft:snow_block
setblock ~-8 ~7 ~5 minecraft:snow_block
setblock ~-4 ~8 ~20 minecraft:snow_block
setblock ~-7 ~15 ~9 minecraft:snow_block
setblock ~-4 ~10 ~13 minecraft:snow_block
setblock ~-11 ~10 ~5 minecraft:snow_block
setblock ~5 ~4 ~4 minecraft:snow_block
setblock ~7 ~14 ~-12 minecraft:snow_block
setblock ~-4 ~9 ~15 minecraft:blue_wool
setblock ~-7 ~24 ~-4 minecraft:snow_block
setblock ~1 ~25 ~9 minecraft:snow_block
setblock ~-11 ~17 ~-2 minecraft:snow_block
setblock ~5 ~12 ~12 minecraft:snow_block
setblock ~4 ~5 ~16 minecraft:snow_block
setblock ~7 ~2 ~11 minecraft:snow_block
setblock ~-3 ~22 ~-8 minecraft:snow_block
setblock ~6 ~3 ~12 minecraft:snow_block
setblock ~-7 ~7 ~15 minecraft:snow_block
setblock ~5 ~4 ~14 minecraft:snow_block
setblock ~-6 ~5 ~10 minecraft:snow_block
setblock ~6 ~10 ~5 minecraft:snow_block
setblock ~4 ~7 ~18 minecraft:snow_block
setblock ~-3 ~15 ~16 minecraft:snow_block
setblock ~9 ~19 ~-6 minecraft:snow_block
setblock ~-8 ~8 ~6 minecraft:blue_wool
setblock ~-9 ~23 ~-1 minecraft:snow_block
setblock ~-7 ~1 ~-2 minecraft:snow_block
setblock ~-7 ~25 ~-1 minecraft:snow_block
setblock ~2 ~10 ~19 minecraft:snow_block
setblock ~2 ~0 ~-2 minecraft:snow_block
setblock ~3 ~8 ~16 minecraft:blue_wool
setblock ~-5 ~17 ~-13 minecraft:snow_block
setblock ~4 ~2 ~-11 minecraft:snow_block
setblock ~-8 ~21 ~-7 minecraft:snow_block
setblock ~-2 ~22 ~-9 minecraft:snow_block
setblock ~-4 ~18 ~-12 minecraft:snow_block
setblock ~-2 ~16 ~15 minecraft:blue_wool
setblock ~-9 ~14 ~-12 minecraft:snow_block
setblock ~-2 ~15 ~15 minecraft:blue_wool
setblock ~1 ~6 ~22 minecraft:snow_block
setblock ~7 ~10 ~5 minecraft:snow_block
setblock ~9 ~8 ~3 minecraft:snow_block
setblock ~-6 ~14 ~10 minecraft:snow_block
setblock ~-5 ~9 ~18 minecraft:snow_block
setblock ~2 ~8 ~5 minecraft:snow_block
setblock ~7 ~5 ~-10 minecraft:snow_block
setblock ~6 ~7 ~8 minecraft:snow_block
setblock ~-1 ~13 ~17 minecraft:snow_block
setblock ~-6 ~15 ~14 minecraft:snow_block
setblock ~8 ~14 ~8 minecraft:snow_block
setblock ~4 ~8 ~17 minecraft:snow_block
setblock ~3 ~16 ~15 minecraft:snow_block
setblock ~-11 ~15 ~-8 minecraft:snow_block
setblock ~2 ~9 ~20 minecraft:snow_block
setblock ~1 ~26 ~-1 minecraft:snow_block
setblock ~6 ~1 ~-8 minecraft:snow_block
setblock ~-8 ~5 ~-10 minecraft:snow_block
setblock ~-6 ~15 ~8 minecraft:snow_block
setblock ~7 ~8 ~8 minecraft:snow_block
setblock ~5 ~0 ~-6 minecraft:snow_block
setblock ~-4 ~3 ~-12 minecraft:snow_block
setblock ~-5 ~9 ~14 minecraft:snow_block
setblock ~-9 ~12 ~6 minecraft:snow_block
setblock ~-6 ~1 ~-8 minecraft:snow_block
setblock ~-4 ~15 ~14 minecraft:snow_block
setblock ~7 ~4 ~3 minecraft:snow_block
setblock ~1 ~9 ~20 minecraft:snow_block
setblock ~-5 ~5 ~18 minecraft:snow_block
setblock ~-6 ~4 ~3 minecraft:snow_block
setblock ~3 ~9 ~6 minecraft:snow_block
setblock ~9 ~9 ~4 minecraft:snow_block
setblock ~-2 ~13 ~16 minecraft:snow_block
setblock ~5 ~6 ~10 minecraft:snow_block
setblock ~-7 ~25 ~2 minecraft:snow_block
setblock ~-5 ~0 ~-3 minecraft:snow_block
setblock ~2 ~6 ~20 minecraft:snow_block
setblock ~1 ~7 ~1 minecraft:snow_block
setblock ~4 ~7 ~14 minecraft:snow_block
setblock ~-5 ~14 ~10 minecraft:snow_block
setblock ~5 ~22 ~9 minecraft:snow_block
setblock ~-8 ~15 ~10 minecraft:snow_block
setblock ~-10 ~21 ~-3 minecraft:snow_block
setblock ~3 ~16 ~-13 minecraft:snow_block
setblock ~5 ~7 ~13 minecraft:snow_block
setblock ~6 ~18 ~-11 minecraft:snow_block
setblock ~-2 ~23 ~11 minecraft:snow_block
setblock ~-7 ~11 ~9 minecraft:snow_block
setblock ~-8 ~11 ~8 minecraft:snow_block
setblock ~-4 ~16 ~-14 minecraft:snow_block
setblock ~-4 ~1 ~-2 minecraft:snow_block
setblock ~3 ~12 ~17 minecraft:snow_block
setblock ~-2 ~10 ~19 minecraft:blue_wool
setblock ~6 ~22 ~8 minecraft:snow_block
setblock ~-7 ~19 ~9 minecraft:snow_block
setblock ~-9 ~20 ~6 minecraft:snow_block
setblock ~-7 ~7 ~9 minecraft:snow_block
setblock ~2 ~9 ~16 minecraft:snow_block
setblock ~-1 ~25 ~9 minecraft:snow_block
setblock ~3 ~9 ~16 minecraft:blue_wool
setblock ~-3 ~16 ~13 minecraft:snow_block
setblock ~-8 ~14 ~11 minecraft:snow_block
setblock ~-10 ~10 ~-8 minecraft:snow_block
setblock ~-2 ~26 ~5 minecraft:snow_block
setblock ~-7 ~9 ~11 minecraft:snow_block
setblock ~4 ~6 ~15 minecraft:snow_block
setblock ~-11 ~10 ~3 minecraft:snow_block
setblock ~-7 ~25 ~5 minecraft:snow_block
setblock ~3 ~10 ~17 minecraft:blue_wool
setblock ~-2 ~11 ~-15 minecraft:snow_block
setblock ~7 ~5 ~3 minecraft:snow_block
setblock ~-3 ~25 ~8 minecraft:snow_block
setblock ~3 ~9 ~15 minecraft:blue_wool
setblock ~7 ~9 ~5 minecraft:blue_wool
setblock ~-2 ~26 ~-2 minecraft:snow_block
setblock ~-5 ~10 ~11 minecraft:snow_block
setblock ~-9 ~14 ~-11 minecraft:snow_block
setblock ~4 ~1 ~-8 minecraft:snow_block
setblock ~-1 ~19 ~15 minecraft:snow_block
setblock ~-6 ~26 ~3 minecraft:snow_block
setblock ~9 ~11 ~-10 minecraft:snow_block
setblock ~8 ~14 ~6 minecraft:snow_block
setblock ~-7 ~16 ~-12 minecraft:snow_block
setblock ~2 ~7 ~19 minecraft:snow_block
setblock ~0 ~12 ~12 minecraft:snow_block
setblock ~5 ~5 ~12 minecraft:snow_block
setblock ~-4 ~8 ~17 minecraft:blue_wool
setblock ~10 ~12 ~-5 minecraft:snow_block
setblock ~6 ~9 ~4 minecraft:snow_block
setblock ~5 ~3 ~14 minecraft:snow_block
setblock ~10 ~6 ~-4 minecraft:snow_block
setblock ~-2 ~17 ~9 minecraft:snow_block
setblock ~0 ~14 ~19 minecraft:snow_block
setblock ~-3 ~9 ~16 minecraft:snow_block
setblock ~-6 ~7 ~12 minecraft:snow_block
setblock ~-1 ~25 ~8 minecraft:snow_block
setblock ~-2 ~1 ~-9 minecraft:snow_block
setblock ~-1 ~18 ~13 minecraft:snow_block
setblock ~-3 ~16 ~10 minecraft:snow_block
setblock ~5 ~25 ~-2 minecraft:snow_block
setblock ~5 ~26 ~1 minecraft:snow_block
setblock ~0 ~17 ~-14 minecraft:snow_block
setblock ~9 ~15 ~5 minecraft:snow_block
setblock ~-3 ~12 ~-15 minecraft:snow_block
setblock ~3 ~11 ~16 minecraft:blue_wool
setblock ~9 ~17 ~-6 minecraft:snow_block
setblock ~-11 ~10 ~-3 minecraft:snow_block
setblock ~-7 ~24 ~-3 minecraft:snow_block
setblock ~-8 ~18 ~-9 minecraft:snow_block
setblock ~-2 ~15 ~17 minecraft:snow_block
setblock ~2 ~12 ~18 minecraft:blue_wool
setblock ~-4 ~7 ~19 minecraft:blue_wool
setblock ~1 ~17 ~16 minecraft:snow_block
setblock ~-4 ~16 ~14 minecraft:snow_block
setblock ~4 ~6 ~14 minecraft:snow_block
setblock ~-8 ~5 ~10 minecraft:snow_block
setblock ~-2 ~14 ~15 minecraft:snow_block
setblock ~7 ~11 ~8 minecraft:snow_block
setblock ~4 ~9 ~12 minecraft:snow_block
setblock ~-6 ~9 ~13 minecraft:snow_block
setblock ~-7 ~8 ~9 minecraft:snow_block
setblock ~4 ~21 ~10 minecraft:snow_block
setblock ~-10 ~20 ~4 minecraft:snow_block
setblock ~-9 ~16 ~10 minecraft:snow_block
setblock ~3 ~9 ~14 minecraft:snow_block
setblock ~8 ~10 ~5 minecraft:snow_block
setblock ~-1 ~13 ~14 minecraft:blue_wool
setblock ~-1 ~25 ~-5 minecraft:snow_block
setblock ~-1 ~13 ~18 minecraft:snow_block
setblock ~-3 ~11 ~18 minecraft:blue_wool
setblock ~-9 ~9 ~-11 minecraft:snow_block
setblock ~1 ~16 ~16 minecraft:snow_block
setblock ~-2 ~4 ~0 minecraft:snow_block
setblock ~-4 ~12 ~18 minecraft:snow_block
setblock ~-1 ~17 ~14 minecraft:snow_block
setblock ~1 ~8 ~0 minecraft:snow_block
setblock ~-3 ~2 ~-10 minecraft:snow_block
setblock ~-8 ~10 ~9 minecraft:snow_block
setblock ~9 ~5 ~-7 minecraft:snow_block
setblock ~7 ~11 ~10 minecraft:snow_block
setblock ~-4 ~7 ~13 minecraft:snow_block
setblock ~-3 ~11 ~17 minecraft:snow_block
setblock ~6 ~10 ~8 minecraft:snow_block
setblock ~-3 ~11 ~16 minecraft:snow_block
setblock ~-2 ~10 ~20 minecraft:snow_block
setblock ~-10 ~4 ~-2 minecraft:snow_block
setblock ~-4 ~11 ~16 minecraft:blue_wool
setblock ~7 ~4 ~9 minecraft:snow_block
setblock ~-7 ~7 ~6 minecraft:snow_block
setblock ~8 ~14 ~-11 minecraft:snow_block
setblock ~9 ~12 ~-10 minecraft:snow_block
setblock ~-5 ~11 ~16 minecraft:snow_block
setblock ~8 ~23 ~5 minecraft:snow_block
setblock ~-8 ~20 ~9 minecraft:snow_block
setblock ~7 ~5 ~11 minecraft:snow_block
setblock ~-7 ~4 ~8 minecraft:snow_block
setblock ~-2 ~9 ~20 minecraft:snow_block
setblock ~3 ~0 ~-7 minecraft:snow_block
setblock ~-10 ~13 ~5 minecraft:snow_block
setblock ~6 ~8 ~-13 minecraft:snow_block
setblock ~-3 ~11 ~15 minecraft:snow_block
setblock ~4 ~11 ~17 minecraft:snow_block
setblock ~-3 ~10 ~15 minecraft:snow_block
setblock ~-4 ~14 ~16 minecraft:snow_block
setblock ~-1 ~20 ~13 minecraft:snow_block
setblock ~-4 ~10 ~14 minecraft:blue_wool
setblock ~-3 ~11 ~19 minecraft:snow_block
setblock ~-1 ~1 ~-9 minecraft:snow_block
setblock ~-7 ~7 ~7 minecraft:snow_block
setblock ~7 ~7 ~3 minecraft:snow_block
setblock ~-4 ~20 ~10 minecraft:snow_block
setblock ~-3 ~9 ~20 minecraft:snow_block
setblock ~-11 ~11 ~7 minecraft:snow_block
setblock ~-7 ~5 ~17 minecraft:snow_block
setblock ~-7 ~14 ~12 minecraft:snow_block
setblock ~-2 ~3 ~0 minecraft:snow_block
setblock ~-6 ~13 ~-14 minecraft:snow_block
setblock ~-5 ~9 ~12 minecraft:snow_block
setblock ~9 ~15 ~-8 minecraft:snow_block
setblock ~-5 ~10 ~13 minecraft:blue_wool
setblock ~-8 ~11 ~9 minecraft:snow_block
setblock ~-5 ~15 ~-14 minecraft:snow_block
setblock ~-10 ~17 ~3 minecraft:snow_block
setblock ~9 ~12 ~9 minecraft:blue_wool
setblock ~5 ~7 ~16 minecraft:snow_block
setblock ~4 ~11 ~14 minecraft:snow_block
setblock ~2 ~4 ~4 minecraft:snow_block
setblock ~2 ~10 ~15 minecraft:snow_block
setblock ~-1 ~0 ~-6 minecraft:snow_block
setblock ~8 ~17 ~6 minecraft:snow_block
setblock ~-8 ~22 ~-6 minecraft:snow_block
setblock ~-4 ~11 ~14 minecraft:snow_block
setblock ~6 ~0 ~-4 minecraft:snow_block
setblock ~-2 ~11 ~19 minecraft:blue_wool
setblock ~-1 ~20 ~-12 minecraft:snow_block
setblock ~-6 ~4 ~15 minecraft:snow_block
setblock ~4 ~12 ~15 minecraft:snow_block
setblock ~-8 ~15 ~11 minecraft:snow_block
setblock ~1 ~11 ~18 minecraft:snow_block
setblock ~1 ~1 ~-9 minecraft:snow_block
setblock ~-11 ~15 ~-2 minecraft:snow_block
setblock ~2 ~9 ~15 minecraft:snow_block
setblock ~1 ~27 ~0 minecraft:snow_block
setblock ~-8 ~9 ~5 minecraft:blue_wool
setblock ~-7 ~13 ~13 minecraft:snow_block
setblock ~1 ~11 ~20 minecraft:snow_block
setblock ~-7 ~1 ~-7 minecraft:snow_block
setblock ~8 ~22 ~-3 minecraft:snow_block
setblock ~-1 ~11 ~20 minecraft:snow_block
setblock ~-3 ~10 ~16 minecraft:snow_block
setblock ~5 ~6 ~18 minecraft:snow_block
setblock ~-9 ~12 ~12 minecraft:snow_block
setblock ~8 ~18 ~9 minecraft:snow_block
setblock ~5 ~7 ~17 minecraft:snow_block
setblock ~-2 ~24 ~10 minecraft:snow_block
setblock ~-5 ~7 ~-13 minecraft:snow_block
setblock ~-7 ~23 ~-6 minecraft:snow_block
setblock ~-3 ~7 ~2 minecraft:snow_block
setblock ~-7 ~3 ~11 minecraft:snow_block
setblock ~5 ~4 ~18 minecraft:snow_block
setblock ~-3 ~10 ~17 minecraft:snow_block
setblock ~-8 ~13 ~-12 minecraft:snow_block
setblock ~-1 ~23 ~11 minecraft:snow_block
setblock ~6 ~8 ~13 minecraft:snow_block
setblock ~-8 ~19 ~10 minecraft:snow_block
setblock ~-1 ~22 ~11 minecraft:snow_block
setblock ~-3 ~21 ~11 minecraft:snow_block
setblock ~-4 ~13 ~16 minecraft:snow_block
setblock ~8 ~14 ~9 minecraft:snow_block
setblock ~3 ~25 ~-3 minecraft:snow_block
setblock ~-3 ~23 ~10 minecraft:snow_block
setblock ~-3 ~3 ~-12 minecraft:snow_block
setblock ~-11 ~8 ~1 minecraft:snow_block
setblock ~-6 ~23 ~9 minecraft:snow_block
setblock ~-3 ~19 ~9 minecraft:snow_block
setblock ~-6 ~3 ~15 minecraft:snow_block
setblock ~-3 ~20 ~11 minecraft:snow_block
setblock ~-5 ~21 ~11 minecraft:snow_block
setblock ~8 ~18 ~-8 minecraft:snow_block
setblock ~-10 ~12 ~-11 minecraft:snow_block
setblock ~-3 ~17 ~13 minecraft:blue_wool
setblock ~-7 ~21 ~9 minecraft:snow_block
setblock ~-7 ~22 ~8 minecraft:snow_block
setblock ~4 ~1 ~-9 minecraft:snow_block
setblock ~1 ~6 ~21 minecraft:snow_block
setblock ~-4 ~10 ~8 minecraft:snow_block
setblock ~7 ~8 ~3 minecraft:snow_block
setblock ~-6 ~3 ~16 minecraft:snow_block
setblock ~2 ~16 ~16 minecraft:snow_block
setblock ~-11 ~9 ~5 minecraft:snow_block
setblock ~-8 ~10 ~10 minecraft:snow_block
setblock ~-8 ~22 ~7 minecraft:snow_block
setblock ~-8 ~21 ~7 minecraft:snow_block
setblock ~-6 ~24 ~7 minecraft:snow_block
setblock ~-10 ~8 ~2 minecraft:snow_block
setblock ~-1 ~0 ~-4 minecraft:snow_block
setblock ~10 ~9 ~0 minecraft:snow_block
setblock ~0 ~26 ~-3 minecraft:snow_block
setblock ~3 ~7 ~17 minecraft:snow_block
setblock ~0 ~4 ~0 minecraft:snow_block
setblock ~-6 ~25 ~6 minecraft:snow_block
setblock ~-6 ~21 ~-9 minecraft:snow_block
setblock ~10 ~9 ~-4 minecraft:snow_block
setblock ~4 ~14 ~9 minecraft:snow_block
setblock ~-3 ~10 ~18 minecraft:blue_wool
setblock ~-7 ~7 ~12 minecraft:snow_block
setblock ~-8 ~20 ~8 minecraft:snow_block
setblock ~2 ~12 ~17 minecraft:blue_wool
setblock ~-11 ~13 ~3 minecraft:snow_block
setblock ~-5 ~25 ~7 minecraft:snow_block
setblock ~-5 ~11 ~14 minecraft:snow_block
setblock ~-4 ~25 ~6 minecraft:snow_block
setblock ~-4 ~25 ~8 minecraft:snow_block
setblock ~-3 ~12 ~17 minecraft:blue_wool
setblock ~-3 ~26 ~7 minecraft:snow_block
setblock ~-7 ~3 ~-11 minecraft:snow_block
setblock ~6 ~3 ~15 minecraft:snow_block
setblock ~2 ~19 ~-12 minecraft:snow_block
setblock ~-6 ~16 ~-12 minecraft:snow_block
setblock ~-2 ~26 ~6 minecraft:snow_block
setblock ~-4 ~7 ~18 minecraft:snow_block
setblock ~1 ~8 ~6 minecraft:snow_block
setblock ~-8 ~3 ~12 minecraft:snow_block
setblock ~-9 ~20 ~5 minecraft:snow_block
setblock ~-4 ~15 ~-14 minecraft:snow_block
setblock ~-5 ~2 ~-10 minecraft:snow_block
setblock ~3 ~13 ~16 minecraft:snow_block
setblock ~8 ~13 ~7 minecraft:snow_block
setblock ~6 ~2 ~11 minecraft:snow_block
setblock ~4 ~17 ~8 minecraft:snow_block
setblock ~-10 ~21 ~4 minecraft:snow_block
setblock ~-3 ~16 ~15 minecraft:snow_block
setblock ~-11 ~10 ~7 minecraft:snow_block
setblock ~-8 ~10 ~6 minecraft:snow_block
setblock ~-9 ~14 ~9 minecraft:snow_block
setblock ~7 ~8 ~11 minecraft:snow_block
setblock ~-3 ~6 ~1 minecraft:snow_block
setblock ~-9 ~20 ~-6 minecraft:snow_block
setblock ~9 ~4 ~-3 minecraft:snow_block
setblock ~-4 ~26 ~6 minecraft:snow_block
setblock ~-11 ~12 ~1 minecraft:snow_block
setblock ~-6 ~4 ~11 minecraft:snow_block
setblock ~-1 ~7 ~21 minecraft:blue_wool
setblock ~-7 ~3 ~2 minecraft:snow_block
setblock ~-3 ~26 ~6 minecraft:snow_block
setblock ~4 ~9 ~18 minecraft:snow_block
setblock ~-9 ~11 ~12 minecraft:snow_block
setblock ~10 ~11 ~9 minecraft:snow_block
setblock ~5 ~12 ~13 minecraft:snow_block
setblock ~7 ~8 ~4 minecraft:snow_block
setblock ~7 ~24 ~3 minecraft:snow_block
setblock ~-2 ~5 ~0 minecraft:snow_block
setblock ~-8 ~2 ~11 minecraft:snow_block
setblock ~-9 ~3 ~-7 minecraft:snow_block
setblock ~5 ~16 ~-13 minecraft:snow_block
setblock ~-6 ~25 ~5 minecraft:snow_block
setblock ~-6 ~25 ~4 minecraft:snow_block
setblock ~7 ~15 ~10 minecraft:snow_block
setblock ~9 ~14 ~-10 minecraft:snow_block
setblock ~-4 ~9 ~13 minecraft:snow_block
setblock ~3 ~7 ~18 minecraft:snow_block
setblock ~-9 ~16 ~-10 minecraft:snow_block
setblock ~-9 ~22 ~4 minecraft:snow_block
setblock ~5 ~15 ~8 minecraft:snow_block
setblock ~-8 ~22 ~-4 minecraft:snow_block
setblock ~10 ~16 ~1 minecraft:snow_block
setblock ~9 ~6 ~-7 minecraft:snow_block
setblock ~3 ~8 ~14 minecraft:snow_block
setblock ~-8 ~24 ~5 minecraft:snow_block
setblock ~-3 ~11 ~-15 minecraft:snow_block
setblock ~-7 ~11 ~12 minecraft:snow_block
setblock ~-8 ~20 ~10 minecraft:snow_block
setblock ~-1 ~14 ~19 minecraft:snow_block
setblock ~-11 ~10 ~0 minecraft:snow_block
setblock ~10 ~14 ~3 minecraft:snow_block
setblock ~6 ~25 ~2 minecraft:snow_block
setblock ~4 ~11 ~15 minecraft:snow_block
setblock ~-9 ~3 ~-1 minecraft:snow_block
setblock ~-2 ~18 ~10 minecraft:snow_block
setblock ~-1 ~13 ~19 minecraft:snow_block
setblock ~-3 ~20 ~-11 minecraft:snow_block
setblock ~-1 ~8 ~19 minecraft:snow_block
setblock ~1 ~10 ~8 minecraft:snow_block
setblock ~-2 ~18 ~15 minecraft:snow_block
setblock ~-5 ~22 ~10 minecraft:snow_block
setblock ~-5 ~23 ~10 minecraft:snow_block
setblock ~-7 ~8 ~11 minecraft:snow_block
setblock ~-6 ~20 ~9 minecraft:snow_block
setblock ~0 ~21 ~12 minecraft:snow_block
setblock ~-8 ~5 ~11 minecraft:snow_block
setblock ~-2 ~13 ~-15 minecraft:snow_block
setblock ~-4 ~22 ~11 minecraft:snow_block
setblock ~8 ~22 ~6 minecraft:snow_block
setblock ~-6 ~16 ~8 minecraft:snow_block
setblock ~-2 ~19 ~13 minecraft:snow_block
setblock ~1 ~9 ~-15 minecraft:snow_block
setblock ~5 ~26 ~3 minecraft:snow_block
setblock ~-8 ~9 ~-12 minecraft:snow_block
setblock ~-2 ~20 ~12 minecraft:snow_block
setblock ~6 ~16 ~-12 minecraft:snow_block
setblock ~-2 ~4 ~-13 minecraft:snow_block
setblock ~-2 ~10 ~10 minecraft:snow_block
setblock ~1 ~18 ~12 minecraft:snow_block
setblock ~-6 ~3 ~1 minecraft:snow_block
setblock ~3 ~17 ~8 minecraft:snow_block
setblock ~-4 ~9 ~18 minecraft:blue_wool
setblock ~-3 ~10 ~20 minecraft:snow_block
setblock ~-4 ~5 ~4 minecraft:snow_block
setblock ~-8 ~8 ~8 minecraft:snow_block
setblock ~-5 ~26 ~1 minecraft:snow_block
setblock ~-3 ~17 ~15 minecraft:snow_block
setblock ~-7 ~18 ~-11 minecraft:snow_block
setblock ~-4 ~24 ~8 minecraft:snow_block
setblock ~-4 ~16 ~15 minecraft:snow_block
setblock ~0 ~4 ~-12 minecraft:snow_block
setblock ~-4 ~17 ~14 minecraft:snow_block
setblock ~4 ~8 ~5 minecraft:snow_block
setblock ~-6 ~16 ~13 minecraft:snow_block
setblock ~-8 ~23 ~-4 minecraft:snow_block
setblock ~-11 ~14 ~-1 minecraft:snow_block
setblock ~-3 ~18 ~11 minecraft:snow_block
setblock ~5 ~24 ~6 minecraft:snow_block
setblock ~-1 ~11 ~19 minecraft:snow_block
setblock ~-3 ~15 ~15 minecraft:snow_block
setblock ~-11 ~11 ~3 minecraft:snow_block
setblock ~-6 ~25 ~3 minecraft:snow_block
setblock ~9 ~13 ~-11 minecraft:snow_block
setblock ~2 ~10 ~12 minecraft:snow_block
setblock ~0 ~15 ~-14 minecraft:snow_block
setblock ~-9 ~14 ~12 minecraft:snow_block
setblock ~-1 ~6 ~22 minecraft:snow_block
setblock ~-4 ~9 ~6 minecraft:snow_block
setblock ~-11 ~12 ~3 minecraft:snow_block
setblock ~4 ~25 ~5 minecraft:snow_block
setblock ~6 ~7 ~15 minecraft:snow_block
setblock ~6 ~3 ~10 minecraft:snow_block
setblock ~-2 ~0 ~-8 minecraft:snow_block
setblock ~-11 ~11 ~4 minecraft:snow_block
setblock ~-10 ~11 ~4 minecraft:snow_block
setblock ~-11 ~12 ~-6 minecraft:snow_block
setblock ~-9 ~13 ~11 minecraft:snow_block
setblock ~-11 ~10 ~4 minecraft:snow_block
setblock ~-10 ~12 ~11 minecraft:snow_block
setblock ~-10 ~12 ~4 minecraft:snow_block
setblock ~-9 ~18 ~7 minecraft:snow_block
setblock ~-3 ~27 ~2 minecraft:snow_block
setblock ~1 ~0 ~-3 minecraft:snow_block
setblock ~-9 ~15 ~8 minecraft:snow_block
setblock ~-9 ~16 ~8 minecraft:snow_block
setblock ~8 ~20 ~-5 minecraft:snow_block
setblock ~7 ~22 ~-6 minecraft:snow_block
setblock ~6 ~6 ~15 minecraft:snow_block
setblock ~-11 ~14 ~-7 minecraft:snow_block
setblock ~-6 ~21 ~11 minecraft:snow_block
setblock ~6 ~6 ~16 minecraft:snow_block
setblock ~1 ~12 ~15 minecraft:snow_block
setblock ~-3 ~17 ~14 minecraft:snow_block
setblock ~-2 ~21 ~-11 minecraft:snow_block
setblock ~-7 ~5 ~15 minecraft:snow_block
setblock ~-3 ~18 ~13 minecraft:snow_block
setblock ~-3 ~15 ~10 minecraft:snow_block
setblock ~-4 ~21 ~10 minecraft:snow_block
setblock ~-10 ~21 ~3 minecraft:snow_block
setblock ~-7 ~14 ~13 minecraft:snow_block
setblock ~3 ~26 ~6 minecraft:snow_block
setblock ~-1 ~7 ~5 minecraft:snow_block
setblock ~4 ~5 ~14 minecraft:snow_block
setblock ~7 ~3 ~11 minecraft:snow_block
setblock ~-7 ~4 ~10 minecraft:snow_block
setblock ~-2 ~16 ~-14 minecraft:snow_block
setblock ~5 ~9 ~-14 minecraft:snow_block
setblock ~4 ~8 ~18 minecraft:snow_block
setblock ~7 ~8 ~10 minecraft:snow_block
setblock ~5 ~10 ~-14 minecraft:snow_block
setblock ~-8 ~16 ~10 minecraft:snow_block
setblock ~-5 ~21 ~10 minecraft:snow_block
setblock ~-8 ~1 ~-3 minecraft:snow_block
setblock ~-6 ~12 ~13 minecraft:snow_block
setblock ~-5 ~15 ~13 minecraft:snow_block
setblock ~-2 ~18 ~11 minecraft:snow_block
setblock ~8 ~13 ~6 minecraft:snow_block
setblock ~10 ~12 ~-2 minecraft:snow_block
setblock ~7 ~6 ~6 minecraft:snow_block
setblock ~4 ~14 ~14 minecraft:snow_block
setblock ~-9 ~10 ~5 minecraft:snow_block
setblock ~-10 ~18 ~4 minecraft:snow_block
setblock ~-9 ~4 ~2 minecraft:snow_block
setblock ~-1 ~9 ~-14 minecraft:snow_block
setblock ~-3 ~19 ~10 minecraft:snow_block
setblock ~3 ~8 ~15 minecraft:snow_block
setblock ~-7 ~15 ~12 minecraft:snow_block
setblock ~-1 ~15 ~-14 minecraft:snow_block
setblock ~-3 ~16 ~16 minecraft:snow_block
setblock ~7 ~22 ~-5 minecraft:snow_block
setblock ~-2 ~17 ~15 minecraft:snow_block
setblock ~8 ~5 ~3 minecraft:snow_block
setblock ~4 ~8 ~15 minecraft:blue_wool
setblock ~2 ~10 ~16 minecraft:snow_block
setblock ~-6 ~8 ~-13 minecraft:snow_block
setblock ~-2 ~5 ~-13 minecraft:snow_block
setblock ~-2 ~12 ~18 minecraft:snow_block
setblock ~-6 ~2 ~1 minecraft:snow_block
setblock ~-1 ~19 ~14 minecraft:snow_block
setblock ~-9 ~13 ~7 minecraft:snow_block
setblock ~9 ~19 ~3 minecraft:snow_block
setblock ~10 ~12 ~2 minecraft:snow_block
setblock ~-4 ~7 ~14 minecraft:snow_block
setblock ~-9 ~12 ~7 minecraft:snow_block
setblock ~-9 ~17 ~5 minecraft:snow_block
setblock ~-9 ~16 ~5 minecraft:snow_block
setblock ~-5 ~8 ~5 minecraft:snow_block
setblock ~6 ~2 ~-9 minecraft:snow_block
setblock ~7 ~6 ~12 minecraft:snow_block
setblock ~-8 ~22 ~6 minecraft:snow_block
setblock ~-10 ~18 ~5 minecraft:snow_block
setblock ~-3 ~8 ~19 minecraft:snow_block
setblock ~2 ~22 ~-8 minecraft:snow_block
setblock ~4 ~5 ~18 minecraft:snow_block
setblock ~1 ~12 ~18 minecraft:snow_block
setblock ~2 ~15 ~-14 minecraft:snow_block
setblock ~6 ~3 ~11 minecraft:snow_block
setblock ~9 ~4 ~0 minecraft:snow_block
setblock ~7 ~18 ~-9 minecraft:snow_block
setblock ~3 ~7 ~20 minecraft:blue_wool
setblock ~-8 ~1 ~-7 minecraft:snow_block
setblock ~8 ~16 ~10 minecraft:snow_block
setblock ~-8 ~6 ~9 minecraft:snow_block
setblock ~-8 ~8 ~5 minecraft:blue_wool
setblock ~4 ~13 ~14 minecraft:snow_block
setblock ~-10 ~18 ~3 minecraft:snow_block
setblock ~5 ~8 ~16 minecraft:snow_block
setblock ~-11 ~17 ~2 minecraft:snow_block
setblock ~-8 ~10 ~8 minecraft:snow_block
setblock ~-10 ~18 ~2 minecraft:snow_block
setblock ~-2 ~5 ~-1 minecraft:snow_block
setblock ~-11 ~17 ~0 minecraft:snow_block
setblock ~-10 ~16 ~5 minecraft:snow_block
setblock ~-3 ~18 ~-12 minecraft:snow_block
setblock ~2 ~17 ~9 minecraft:snow_block
setblock ~-10 ~15 ~5 minecraft:snow_block
setblock ~8 ~20 ~9 minecraft:snow_block
setblock ~-3 ~23 ~11 minecraft:snow_block
setblock ~-10 ~13 ~4 minecraft:snow_block
setblock ~-5 ~5 ~-13 minecraft:snow_block
setblock ~-11 ~14 ~2 minecraft:snow_block
setblock ~-4 ~25 ~-3 minecraft:snow_block
setblock ~6 ~7 ~10 minecraft:snow_block
setblock ~2 ~8 ~18 minecraft:snow_block
setblock ~-3 ~17 ~12 minecraft:snow_block
setblock ~7 ~24 ~4 minecraft:snow_block
setblock ~-10 ~14 ~3 minecraft:snow_block
setblock ~-1 ~25 ~-4 minecraft:snow_block
setblock ~-11 ~16 ~2 minecraft:snow_block
setblock ~-4 ~15 ~10 minecraft:snow_block
setblock ~-1 ~26 ~7 minecraft:snow_block
setblock ~-8 ~12 ~-13 minecraft:snow_block
setblock ~-10 ~15 ~3 minecraft:snow_block
setblock ~-9 ~2 ~-6 minecraft:snow_block
setblock ~-4 ~10 ~15 minecraft:blue_wool
setblock ~7 ~21 ~8 minecraft:snow_block
setblock ~-4 ~15 ~8 minecraft:snow_block
setblock ~-9 ~4 ~-9 minecraft:snow_block
setblock ~-5 ~14 ~14 minecraft:snow_block
setblock ~7 ~5 ~9 minecraft:snow_block
setblock ~-8 ~12 ~13 minecraft:snow_block
setblock ~-10 ~22 ~1 minecraft:snow_block
setblock ~7 ~9 ~-13 minecraft:snow_block
setblock ~-6 ~4 ~16 minecraft:snow_block
setblock ~-7 ~10 ~5 minecraft:snow_block
setblock ~4 ~9 ~15 minecraft:snow_block
setblock ~-11 ~10 ~2 minecraft:snow_block
setblock ~5 ~8 ~13 minecraft:blue_wool
setblock ~-9 ~19 ~-8 minecraft:snow_block
setblock ~9 ~13 ~5 minecraft:snow_block
setblock ~-9 ~16 ~7 minecraft:snow_block
setblock ~-9 ~24 ~3 minecraft:snow_block
setblock ~3 ~24 ~9 minecraft:snow_block
setblock ~-7 ~9 ~-13 minecraft:snow_block
setblock ~10 ~11 ~4 minecraft:snow_block
setblock ~6 ~5 ~4 minecraft:snow_block
setblock ~9 ~20 ~2 minecraft:snow_block
setblock ~-3 ~13 ~-14 minecraft:snow_block
setblock ~-8 ~24 ~1 minecraft:snow_block
setblock ~-1 ~7 ~20 minecraft:snow_block
setblock ~-8 ~25 ~2 minecraft:snow_block
setblock ~-2 ~17 ~11 minecraft:snow_block
setblock ~-4 ~26 ~4 minecraft:snow_block
setblock ~7 ~7 ~7 minecraft:snow_block
setblock ~-9 ~13 ~-11 minecraft:snow_block
setblock ~-4 ~26 ~2 minecraft:snow_block
setblock ~-11 ~14 ~0 minecraft:snow_block
setblock ~-5 ~18 ~-12 minecraft:snow_block
setblock ~9 ~21 ~-1 minecraft:snow_block
setblock ~1 ~6 ~-14 minecraft:snow_block
setblock ~1 ~10 ~18 minecraft:snow_block
setblock ~-2 ~3 ~-12 minecraft:snow_block
setblock ~-2 ~27 ~4 minecraft:snow_block
setblock ~7 ~18 ~9 minecraft:snow_block
setblock ~-3 ~27 ~3 minecraft:snow_block
setblock ~-9 ~12 ~-11 minecraft:snow_block
setblock ~-3 ~7 ~6 minecraft:snow_block
setblock ~2 ~10 ~17 minecraft:snow_block
setblock ~10 ~7 ~-4 minecraft:snow_block
setblock ~7 ~9 ~10 minecraft:snow_block
setblock ~-2 ~27 ~3 minecraft:snow_block
setblock ~-6 ~22 ~-7 minecraft:snow_block
setblock ~6 ~1 ~-2 minecraft:snow_block
setblock ~-7 ~3 ~16 minecraft:snow_block
setblock ~6 ~8 ~11 minecraft:snow_block
setblock ~-1 ~27 ~4 minecraft:snow_block
setblock ~-4 ~6 ~18 minecraft:snow_block
setblock ~-2 ~7 ~-14 minecraft:snow_block
setblock ~-5 ~6 ~16 minecraft:snow_block
setblock ~6 ~11 ~10 minecraft:snow_block
setblock ~-7 ~14 ~11 minecraft:snow_block
setblock ~-5 ~26 ~4 minecraft:snow_block
setblock ~-7 ~18 ~9 minecraft:snow_block
setblock ~6 ~1 ~-9 minecraft:snow_block
setblock ~-7 ~18 ~8 minecraft:snow_block
setblock ~-9 ~2 ~-2 minecraft:snow_block
setblock ~-6 ~4 ~14 minecraft:snow_block
setblock ~-1 ~26 ~-3 minecraft:snow_block
setblock ~-8 ~6 ~-12 minecraft:snow_block
setblock ~5 ~23 ~-6 minecraft:snow_block
setblock ~-3 ~19 ~11 minecraft:snow_block
setblock ~8 ~17 ~7 minecraft:snow_block
setblock ~-8 ~15 ~9 minecraft:snow_block
setblock ~-10 ~7 ~0 minecraft:snow_block
setblock ~-3 ~17 ~11 minecraft:snow_block
setblock ~-4 ~15 ~13 minecraft:snow_block
setblock ~-9 ~3 ~-9 minecraft:snow_block
setblock ~4 ~8 ~13 minecraft:snow_block
setblock ~6 ~6 ~8 minecraft:snow_block
setblock ~3 ~10 ~18 minecraft:snow_block
setblock ~-5 ~14 ~12 minecraft:snow_block
setblock ~-5 ~18 ~9 minecraft:snow_block
setblock ~-7 ~8 ~-13 minecraft:snow_block
setblock ~-2 ~8 ~20 minecraft:blue_wool
setblock ~-5 ~8 ~14 minecraft:blue_wool
setblock ~-5 ~14 ~11 minecraft:snow_block
setblock ~1 ~26 ~5 minecraft:snow_block
setblock ~4 ~5 ~19 minecraft:snow_block
setblock ~2 ~25 ~-5 minecraft:snow_block
setblock ~-1 ~8 ~20 minecraft:snow_block
setblock ~-7 ~15 ~8 minecraft:snow_block
setblock ~-9 ~19 ~7 minecraft:snow_block
setblock ~5 ~6 ~11 minecraft:snow_block
setblock ~-4 ~18 ~9 minecraft:snow_block
setblock ~-7 ~8 ~14 minecraft:snow_block
setblock ~6 ~24 ~-4 minecraft:snow_block
setblock ~-3 ~16 ~9 minecraft:snow_block
setblock ~5 ~2 ~-1 minecraft:snow_block
setblock ~8 ~14 ~10 minecraft:snow_block
setblock ~0 ~11 ~20 minecraft:snow_block
setblock ~10 ~17 ~-2 minecraft:snow_block
setblock ~8 ~11 ~12 minecraft:snow_block
setblock ~-4 ~14 ~15 minecraft:snow_block
setblock ~1 ~8 ~20 minecraft:blue_wool
setblock ~-3 ~19 ~-12 minecraft:snow_block
setblock ~7 ~9 ~7 minecraft:snow_block
setblock ~-1 ~24 ~9 minecraft:snow_block
setblock ~-5 ~0 ~-5 minecraft:snow_block
setblock ~-4 ~16 ~8 minecraft:snow_block
setblock ~6 ~8 ~6 minecraft:snow_block
setblock ~0 ~6 ~22 minecraft:snow_block
setblock ~-6 ~5 ~4 minecraft:snow_block
setblock ~-6 ~22 ~9 minecraft:snow_block
setblock ~5 ~3 ~15 minecraft:snow_block
setblock ~-1 ~26 ~-1 minecraft:snow_block
setblock ~-10 ~10 ~5 minecraft:snow_block
setblock ~-5 ~15 ~8 minecraft:snow_block
setblock ~2 ~10 ~20 minecraft:snow_block
setblock ~10 ~13 ~-6 minecraft:snow_block
setblock ~-2 ~17 ~-14 minecraft:snow_block
setblock ~-2 ~25 ~-5 minecraft:snow_block
setblock ~-6 ~19 ~9 minecraft:snow_block
setblock ~-11 ~11 ~-5 minecraft:snow_block
setblock ~-4 ~15 ~9 minecraft:snow_block
setblock ~-5 ~22 ~11 minecraft:snow_block
setblock ~-7 ~5 ~10 minecraft:snow_block
setblock ~6 ~10 ~9 minecraft:snow_block
setblock ~5 ~4 ~13 minecraft:snow_block
setblock ~-11 ~19 ~0 minecraft:snow_block
setblock ~-4 ~7 ~17 minecraft:snow_block
setblock ~-11 ~19 ~-1 minecraft:snow_block
setblock ~-5 ~22 ~-8 minecraft:snow_block
setblock ~-3 ~18 ~-13 minecraft:snow_block
setblock ~3 ~14 ~10 minecraft:snow_block
setblock ~-2 ~12 ~20 minecraft:snow_block
setblock ~0 ~13 ~18 minecraft:snow_block
setblock ~2 ~2 ~-10 minecraft:snow_block
setblock ~6 ~21 ~-7 minecraft:snow_block
setblock ~-10 ~20 ~-1 minecraft:snow_block
setblock ~6 ~3 ~9 minecraft:snow_block
setblock ~-10 ~21 ~0 minecraft:snow_block
setblock ~-6 ~14 ~14 minecraft:snow_block
setblock ~-3 ~25 ~-5 minecraft:snow_block
setblock ~-10 ~22 ~0 minecraft:snow_block
setblock ~-9 ~17 ~8 minecraft:snow_block
setblock ~-8 ~24 ~-1 minecraft:snow_block
setblock ~4 ~15 ~13 minecraft:snow_block
setblock ~-5 ~26 ~3 minecraft:snow_block
setblock ~4 ~5 ~15 minecraft:snow_block
setblock ~-8 ~24 ~0 minecraft:snow_block
setblock ~3 ~9 ~13 minecraft:snow_block
setblock ~1 ~1 ~-10 minecraft:snow_block
setblock ~-9 ~8 ~5 minecraft:snow_block
setblock ~-9 ~7 ~-10 minecraft:snow_block
setblock ~-2 ~14 ~11 minecraft:snow_block
setblock ~-10 ~22 ~-1 minecraft:snow_block
setblock ~9 ~5 ~-6 minecraft:snow_block
setblock ~-5 ~13 ~-14 minecraft:snow_block
setblock ~-2 ~25 ~7 minecraft:snow_block
setblock ~-3 ~13 ~18 minecraft:snow_block
setblock ~-6 ~7 ~18 minecraft:snow_block
setblock ~-6 ~25 ~-1 minecraft:snow_block
setblock ~7 ~7 ~10 minecraft:snow_block
setblock ~-11 ~13 ~0 minecraft:snow_block
setblock ~-3 ~6 ~21 minecraft:snow_block
setblock ~-9 ~22 ~-3 minecraft:snow_block
setblock ~6 ~25 ~5 minecraft:snow_block
setblock ~-9 ~6 ~-9 minecraft:snow_block
setblock ~6 ~17 ~-11 minecraft:snow_block
setblock ~-5 ~26 ~-1 minecraft:snow_block
setblock ~5 ~6 ~12 minecraft:snow_block
setblock ~0 ~8 ~-2 minecraft:snow_block
setblock ~-6 ~26 ~0 minecraft:snow_block
setblock ~10 ~18 ~1 minecraft:snow_block
setblock ~-3 ~14 ~16 minecraft:snow_block
setblock ~-7 ~25 ~-2 minecraft:snow_block
setblock ~-4 ~8 ~13 minecraft:snow_block
setblock ~-3 ~7 ~1 minecraft:snow_block
setblock ~-5 ~24 ~7 minecraft:snow_block
setblock ~-8 ~24 ~3 minecraft:snow_block
setblock ~-6 ~26 ~1 minecraft:snow_block
setblock ~3 ~10 ~11 minecraft:snow_block
setblock ~-10 ~8 ~-9 minecraft:snow_block
setblock ~-5 ~14 ~-14 minecraft:snow_block
setblock ~-8 ~10 ~-13 minecraft:snow_block
setblock ~-3 ~27 ~0 minecraft:snow_block
setblock ~-9 ~14 ~11 minecraft:snow_block
setblock ~-5 ~23 ~-6 minecraft:snow_block
setblock ~10 ~9 ~4 minecraft:snow_block
setblock ~-2 ~0 ~-4 minecraft:snow_block
setblock ~3 ~7 ~21 minecraft:snow_block
setblock ~3 ~10 ~13 minecraft:snow_block
setblock ~-4 ~26 ~-2 minecraft:snow_block
setblock ~3 ~6 ~-13 minecraft:snow_block
setblock ~5 ~3 ~16 minecraft:snow_block
setblock ~3 ~8 ~18 minecraft:blue_wool
setblock ~-4 ~26 ~1 minecraft:snow_block
setblock ~-9 ~18 ~8 minecraft:snow_block
setblock ~-4 ~18 ~-13 minecraft:snow_block
setblock ~8 ~11 ~5 minecraft:snow_block
setblock ~6 ~20 ~-8 minecraft:snow_block
setblock ~-7 ~17 ~8 minecraft:snow_block
setblock ~-2 ~27 ~1 minecraft:snow_block
setblock ~-5 ~6 ~17 minecraft:snow_block
setblock ~4 ~8 ~16 minecraft:snow_block
setblock ~5 ~10 ~13 minecraft:snow_block
setblock ~9 ~3 ~-1 minecraft:snow_block
setblock ~-4 ~14 ~14 minecraft:snow_block
setblock ~-5 ~8 ~18 minecraft:snow_block
setblock ~7 ~10 ~-12 minecraft:snow_block
setblock ~-7 ~6 ~16 minecraft:snow_block
setblock ~-9 ~21 ~-5 minecraft:snow_block
setblock ~-2 ~19 ~11 minecraft:snow_block
setblock ~2 ~23 ~-8 minecraft:snow_block
setblock ~7 ~6 ~4 minecraft:snow_block
setblock ~-1 ~14 ~12 minecraft:snow_block
setblock ~-5 ~5 ~14 minecraft:snow_block
setblock ~-10 ~13 ~10 minecraft:snow_block
setblock ~5 ~7 ~15 minecraft:snow_block
setblock ~-10 ~13 ~11 minecraft:snow_block
setblock ~7 ~23 ~-4 minecraft:snow_block
setblock ~4 ~6 ~-13 minecraft:snow_block
setblock ~9 ~12 ~8 minecraft:snow_block
setblock ~-6 ~8 ~11 minecraft:snow_block
setblock ~-4 ~13 ~14 minecraft:snow_block
setblock ~-11 ~14 ~-3 minecraft:snow_block
setblock ~1 ~8 ~7 minecraft:snow_block
setblock ~2 ~11 ~18 minecraft:blue_wool
setblock ~-5 ~11 ~13 minecraft:snow_block
setblock ~-4 ~5 ~20 minecraft:snow_block
setblock ~1 ~7 ~21 minecraft:blue_wool
setblock ~2 ~8 ~17 minecraft:snow_block
setblock ~0 ~23 ~11 minecraft:snow_block
setblock ~-1 ~23 ~10 minecraft:snow_block
setblock ~6 ~8 ~9 minecraft:snow_block
setblock ~-5 ~12 ~14 minecraft:snow_block
setblock ~-1 ~8 ~-2 minecraft:snow_block
setblock ~4 ~0 ~-7 minecraft:snow_block
setblock ~-5 ~20 ~-11 minecraft:snow_block
setblock ~10 ~13 ~-8 minecraft:snow_block
setblock ~3 ~25 ~7 minecraft:snow_block
setblock ~3 ~17 ~13 minecraft:snow_block
setblock ~-4 ~9 ~16 minecraft:blue_wool
setblock ~10 ~8 ~-4 minecraft:snow_block
setblock ~8 ~13 ~9 minecraft:snow_block
setblock ~-9 ~17 ~6 minecraft:snow_block
setblock ~-2 ~15 ~16 minecraft:snow_block
setblock ~9 ~19 ~-3 minecraft:snow_block
setblock ~3 ~21 ~-10 minecraft:snow_block
setblock ~-2 ~6 ~21 minecraft:snow_block
setblock ~-6 ~2 ~-1 minecraft:snow_block
setblock ~-8 ~9 ~-13 minecraft:snow_block
setblock ~-11 ~13 ~-7 minecraft:snow_block
setblock ~3 ~12 ~18 minecraft:snow_block
setblock ~-9 ~11 ~-11 minecraft:snow_block
setblock ~-5 ~13 ~13 minecraft:snow_block
setblock ~-3 ~15 ~11 minecraft:snow_block
setblock ~2 ~25 ~7 minecraft:snow_block
setblock ~-5 ~8 ~13 minecraft:snow_block
setblock ~-10 ~12 ~12 minecraft:snow_block
setblock ~-4 ~8 ~16 minecraft:blue_wool
setblock ~-10 ~11 ~10 minecraft:snow_block
setblock ~-11 ~12 ~8 minecraft:snow_block
setblock ~-11 ~11 ~6 minecraft:snow_block
setblock ~-6 ~18 ~8 minecraft:snow_block
setblock ~1 ~7 ~22 minecraft:snow_block
setblock ~-11 ~9 ~4 minecraft:snow_block
setblock ~-10 ~16 ~3 minecraft:snow_block
setblock ~-1 ~21 ~12 minecraft:snow_block
setblock ~-10 ~6 ~-4 minecraft:snow_block
setblock ~3 ~2 ~-10 minecraft:snow_block
setblock ~-10 ~14 ~4 minecraft:snow_block
setblock ~-2 ~7 ~2 minecraft:snow_block
setblock ~7 ~11 ~9 minecraft:snow_block
setblock ~10 ~19 ~2 minecraft:snow_block
setblock ~-11 ~13 ~-1 minecraft:snow_block
setblock ~-10 ~5 ~-4 minecraft:snow_block
setblock ~-7 ~5 ~16 minecraft:snow_block
setblock ~0 ~8 ~-1 minecraft:snow_block
setblock ~-11 ~16 ~-5 minecraft:snow_block
setblock ~-7 ~9 ~10 minecraft:snow_block
setblock ~-1 ~26 ~-4 minecraft:snow_block
setblock ~-2 ~25 ~-4 minecraft:snow_block
setblock ~10 ~17 ~-5 minecraft:snow_block
setblock ~-2 ~26 ~-4 minecraft:snow_block
setblock ~8 ~24 ~1 minecraft:snow_block
setblock ~-4 ~15 ~11 minecraft:snow_block
setblock ~-5 ~24 ~-6 minecraft:snow_block
setblock ~9 ~11 ~6 minecraft:blue_wool
setblock ~10 ~6 ~-2 minecraft:snow_block
setblock ~-5 ~24 ~-5 minecraft:snow_block
setblock ~2 ~11 ~17 minecraft:snow_block
setblock ~-1 ~10 ~20 minecraft:snow_block
setblock ~-4 ~24 ~-5 minecraft:snow_block
setblock ~-9 ~23 ~0 minecraft:snow_block
setblock ~6 ~7 ~-12 minecraft:snow_block
setblock ~-4 ~24 ~-6 minecraft:snow_block
setblock ~-9 ~13 ~8 minecraft:snow_block
setblock ~2 ~5 ~5 minecraft:snow_block
setblock ~2 ~14 ~17 minecraft:snow_block
setblock ~3 ~5 ~20 minecraft:snow_block
setblock ~-1 ~7 ~-1 minecraft:snow_block
setblock ~-3 ~15 ~-14 minecraft:snow_block
setblock ~5 ~2 ~0 minecraft:snow_block
setblock ~6 ~9 ~9 minecraft:snow_block
setblock ~-3 ~26 ~-3 minecraft:snow_block
setblock ~-9 ~16 ~6 minecraft:snow_block
setblock ~-4 ~0 ~-7 minecraft:snow_block
setblock ~0 ~20 ~14 minecraft:snow_block
setblock ~-5 ~20 ~-10 minecraft:snow_block
setblock ~5 ~4 ~11 minecraft:snow_block
setblock ~1 ~5 ~0 minecraft:snow_block
setblock ~-8 ~22 ~-5 minecraft:snow_block
setblock ~10 ~15 ~-4 minecraft:snow_block
setblock ~-7 ~23 ~-5 minecraft:snow_block
setblock ~-10 ~21 ~2 minecraft:snow_block
setblock ~-10 ~22 ~2 minecraft:snow_block
setblock ~-1 ~9 ~8 minecraft:snow_block
setblock ~-3 ~12 ~19 minecraft:snow_block
setblock ~-3 ~24 ~8 minecraft:snow_block
setblock ~3 ~7 ~15 minecraft:snow_block
setblock ~0 ~10 ~20 minecraft:snow_block
setblock ~-9 ~22 ~-4 minecraft:snow_block
setblock ~4 ~7 ~-14 minecraft:snow_block
setblock ~9 ~4 ~-6 minecraft:snow_block
setblock ~-2 ~24 ~-7 minecraft:snow_block
setblock ~-9 ~11 ~11 minecraft:snow_block
setblock ~-11 ~19 ~-3 minecraft:snow_block
setblock ~-10 ~20 ~-3 minecraft:snow_block
setblock ~-2 ~25 ~8 minecraft:snow_block
setblock ~-7 ~22 ~-7 minecraft:snow_block
setblock ~-6 ~24 ~8 minecraft:snow_block
setblock ~-4 ~22 ~10 minecraft:snow_block
setblock ~-3 ~5 ~-13 minecraft:snow_block
setblock ~-11 ~17 ~-3 minecraft:snow_block
setblock ~3 ~6 ~-14 minecraft:snow_block
setblock ~-11 ~16 ~-2 minecraft:snow_block
setblock ~-5 ~6 ~13 minecraft:snow_block
setblock ~-11 ~15 ~-1 minecraft:snow_block
setblock ~8 ~15 ~-11 minecraft:snow_block
setblock ~4 ~12 ~13 minecraft:snow_block
setblock ~-7 ~6 ~15 minecraft:snow_block
setblock ~-11 ~15 ~0 minecraft:snow_block
setblock ~3 ~11 ~17 minecraft:blue_wool
setblock ~-11 ~11 ~0 minecraft:snow_block
setblock ~3 ~15 ~-14 minecraft:snow_block
setblock ~-11 ~12 ~0 minecraft:snow_block
setblock ~-11 ~10 ~1 minecraft:snow_block
setblock ~-4 ~27 ~1 minecraft:snow_block
setblock ~-6 ~7 ~17 minecraft:snow_block
setblock ~-10 ~20 ~-5 minecraft:snow_block
setblock ~-10 ~19 ~-6 minecraft:snow_block
setblock ~-10 ~19 ~-7 minecraft:snow_block
setblock ~-10 ~18 ~-6 minecraft:snow_block
setblock ~-11 ~18 ~-5 minecraft:snow_block
setblock ~-7 ~5 ~4 minecraft:snow_block
setblock ~-10 ~13 ~-11 minecraft:snow_block
setblock ~-9 ~15 ~-11 minecraft:snow_block
setblock ~-7 ~9 ~5 minecraft:snow_block
setblock ~4 ~7 ~19 minecraft:snow_block
setblock ~-2 ~9 ~21 minecraft:snow_block
setblock ~8 ~12 ~9 minecraft:snow_block
setblock ~-1 ~6 ~-13 minecraft:snow_block
setblock ~-9 ~14 ~6 minecraft:snow_block
setblock ~-8 ~5 ~4 minecraft:snow_block
setblock ~-9 ~20 ~-5 minecraft:snow_block
setblock ~-10 ~16 ~-8 minecraft:snow_block
setblock ~-8 ~21 ~-6 minecraft:snow_block
setblock ~-6 ~5 ~17 minecraft:blue_wool
setblock ~-6 ~22 ~10 minecraft:snow_block
setblock ~4 ~10 ~9 minecraft:snow_block
setblock ~-6 ~21 ~-8 minecraft:snow_block
setblock ~10 ~13 ~-4 minecraft:snow_block
setblock ~3 ~6 ~19 minecraft:snow_block
setblock ~-5 ~25 ~5 minecraft:snow_block
setblock ~-7 ~22 ~-6 minecraft:snow_block
setblock ~-9 ~15 ~7 minecraft:snow_block
setblock ~-6 ~23 ~-6 minecraft:snow_block
setblock ~10 ~16 ~0 minecraft:snow_block
setblock ~0 ~10 ~12 minecraft:snow_block
setblock ~-4 ~23 ~-7 minecraft:snow_block
setblock ~3 ~4 ~-13 minecraft:snow_block
setblock ~-2 ~13 ~14 minecraft:snow_block
setblock ~9 ~16 ~3 minecraft:snow_block
setblock ~-8 ~4 ~12 minecraft:snow_block
setblock ~7 ~16 ~8 minecraft:snow_block
setblock ~7 ~14 ~13 minecraft:snow_block
setblock ~-4 ~23 ~-8 minecraft:snow_block
setblock ~-3 ~24 ~-7 minecraft:snow_block
setblock ~1 ~9 ~7 minecraft:snow_block
setblock ~-9 ~15 ~9 minecraft:snow_block
setblock ~-10 ~14 ~-10 minecraft:snow_block
setblock ~1 ~20 ~13 minecraft:snow_block
setblock ~-9 ~19 ~10 minecraft:snow_block
setblock ~7 ~20 ~8 minecraft:snow_block
setblock ~-11 ~19 ~1 minecraft:snow_block
setblock ~3 ~9 ~17 minecraft:blue_wool
setblock ~9 ~22 ~1 minecraft:snow_block
setblock ~-8 ~3 ~3 minecraft:snow_block
setblock ~1 ~14 ~-15 minecraft:snow_block
setblock ~6 ~5 ~8 minecraft:snow_block
setblock ~-2 ~23 ~-8 minecraft:snow_block
setblock ~-2 ~0 ~-6 minecraft:snow_block
setblock ~-6 ~9 ~4 minecraft:snow_block
setblock ~-2 ~23 ~-7 minecraft:snow_block
setblock ~4 ~5 ~13 minecraft:snow_block
setblock ~-3 ~10 ~-14 minecraft:snow_block
setblock ~-10 ~18 ~-8 minecraft:snow_block
setblock ~9 ~4 ~-4 minecraft:snow_block
setblock ~-8 ~16 ~9 minecraft:snow_block
setblock ~-9 ~18 ~-8 minecraft:snow_block
setblock ~-1 ~8 ~6 minecraft:snow_block
setblock ~-6 ~5 ~16 minecraft:snow_block
setblock ~-8 ~19 ~-8 minecraft:snow_block
setblock ~-7 ~20 ~-8 minecraft:snow_block
setblock ~9 ~6 ~-8 minecraft:snow_block
setblock ~-7 ~20 ~-9 minecraft:snow_block
setblock ~6 ~9 ~11 minecraft:snow_block
setblock ~9 ~17 ~3 minecraft:snow_block
setblock ~8 ~21 ~-3 minecraft:snow_block
setblock ~-2 ~22 ~11 minecraft:snow_block
setblock ~-7 ~15 ~-12 minecraft:snow_block
setblock ~-8 ~17 ~8 minecraft:snow_block
setblock ~-5 ~4 ~18 minecraft:snow_block
setblock ~-8 ~15 ~-12 minecraft:snow_block
setblock ~5 ~4 ~3 minecraft:snow_block
setblock ~-6 ~17 ~8 minecraft:snow_block
setblock ~-7 ~14 ~-13 minecraft:snow_block
setblock ~3 ~10 ~15 minecraft:blue_wool
setblock ~-2 ~17 ~12 minecraft:blue_wool
setblock ~-8 ~25 ~1 minecraft:snow_block
setblock ~-7 ~17 ~-12 minecraft:snow_block
setblock ~-4 ~0 ~-8 minecraft:snow_block
setblock ~-8 ~17 ~-11 minecraft:snow_block
setblock ~8 ~6 ~3 minecraft:snow_block
setblock ~-2 ~8 ~21 minecraft:snow_block
setblock ~-9 ~17 ~-10 minecraft:snow_block
setblock ~-7 ~10 ~6 minecraft:snow_block
setblock ~-6 ~16 ~-13 minecraft:snow_block
setblock ~-5 ~17 ~-12 minecraft:snow_block
setblock ~4 ~0 ~-3 minecraft:snow_block
setblock ~7 ~10 ~9 minecraft:snow_block
setblock ~-6 ~18 ~-12 minecraft:snow_block
setblock ~-5 ~13 ~14 minecraft:snow_block
setblock ~-6 ~20 ~-10 minecraft:snow_block
setblock ~-4 ~14 ~12 minecraft:snow_block
setblock ~-6 ~10 ~5 minecraft:snow_block
setblock ~-6 ~5 ~19 minecraft:snow_block
setblock ~-6 ~19 ~-11 minecraft:snow_block
setblock ~-9 ~18 ~6 minecraft:snow_block
setblock ~-7 ~7 ~3 minecraft:snow_block
setblock ~-4 ~20 ~-10 minecraft:snow_block
setblock ~1 ~0 ~-6 minecraft:snow_block
setblock ~2 ~26 ~-3 minecraft:snow_block
setblock ~-4 ~21 ~-9 minecraft:snow_block
setblock ~-5 ~15 ~-13 minecraft:snow_block
setblock ~-4 ~17 ~-13 minecraft:snow_block
setblock ~-8 ~6 ~12 minecraft:snow_block
setblock ~-2 ~15 ~-14 minecraft:snow_block
setblock ~-7 ~7 ~13 minecraft:snow_block
setblock ~-4 ~19 ~-12 minecraft:snow_block
setblock ~-8 ~9 ~8 minecraft:snow_block
setblock ~7 ~23 ~-3 minecraft:snow_block
setblock ~-11 ~12 ~9 minecraft:snow_block
setblock ~6 ~5 ~16 minecraft:snow_block
setblock ~-7 ~11 ~-13 minecraft:snow_block
setblock ~-10 ~13 ~9 minecraft:snow_block
setblock ~-5 ~11 ~-14 minecraft:snow_block
setblock ~-11 ~16 ~-6 minecraft:snow_block
setblock ~-6 ~11 ~-14 minecraft:snow_block
setblock ~-2 ~8 ~2 minecraft:snow_block
setblock ~-5 ~16 ~13 minecraft:snow_block
setblock ~-2 ~12 ~-15 minecraft:snow_block
setblock ~-3 ~13 ~-15 minecraft:snow_block
setblock ~-4 ~3 ~-11 minecraft:snow_block
setblock ~-2 ~14 ~-14 minecraft:snow_block
setblock ~5 ~18 ~-12 minecraft:snow_block
setblock ~-9 ~10 ~-12 minecraft:snow_block
setblock ~-11 ~11 ~-8 minecraft:snow_block
setblock ~4 ~9 ~13 minecraft:blue_wool
setblock ~8 ~17 ~8 minecraft:snow_block
setblock ~2 ~6 ~5 minecraft:snow_block
setblock ~1 ~23 ~10 minecraft:snow_block
setblock ~-5 ~9 ~-14 minecraft:snow_block
setblock ~-4 ~9 ~-14 minecraft:snow_block
setblock ~2 ~26 ~6 minecraft:snow_block
setblock ~-11 ~8 ~-2 minecraft:snow_block
setblock ~-6 ~7 ~13 minecraft:snow_block
setblock ~-6 ~8 ~-14 minecraft:snow_block
setblock ~-1 ~20 ~14 minecraft:snow_block
setblock ~-9 ~18 ~9 minecraft:snow_block
setblock ~-3 ~9 ~-14 minecraft:snow_block
setblock ~-3 ~8 ~-14 minecraft:snow_block
setblock ~3 ~25 ~8 minecraft:snow_block
setblock ~-2 ~9 ~18 minecraft:snow_block
setblock ~-3 ~14 ~14 minecraft:snow_block
setblock ~1 ~5 ~-13 minecraft:snow_block
setblock ~-2 ~7 ~5 minecraft:snow_block
setblock ~1 ~11 ~19 minecraft:blue_wool
setblock ~-4 ~8 ~-14 minecraft:snow_block
setblock ~-4 ~9 ~7 minecraft:snow_block
setblock ~4 ~23 ~10 minecraft:snow_block
setblock ~-8 ~23 ~6 minecraft:snow_block
setblock ~-7 ~11 ~10 minecraft:snow_block
setblock ~-1 ~11 ~-15 minecraft:snow_block
setblock ~-8 ~15 ~12 minecraft:snow_block
setblock ~-1 ~10 ~-15 minecraft:snow_block
setblock ~7 ~11 ~13 minecraft:snow_block
setblock ~-6 ~14 ~-14 minecraft:snow_block
setblock ~5 ~6 ~16 minecraft:snow_block
setblock ~-8 ~7 ~12 minecraft:snow_block
setblock ~6 ~8 ~7 minecraft:snow_block
setblock ~-10 ~21 ~-4 minecraft:snow_block
setblock ~-1 ~9 ~-15 minecraft:snow_block
setblock ~-2 ~9 ~-15 minecraft:snow_block
setblock ~-6 ~24 ~-5 minecraft:snow_block
setblock ~1 ~6 ~-1 minecraft:snow_block
setblock ~-7 ~6 ~-12 minecraft:snow_block
setblock ~-9 ~9 ~5 minecraft:snow_block
setblock ~7 ~3 ~9 minecraft:snow_block
setblock ~-9 ~6 ~-11 minecraft:snow_block
setblock ~-10 ~7 ~-10 minecraft:snow_block
setblock ~-9 ~8 ~-11 minecraft:snow_block
setblock ~-1 ~3 ~0 minecraft:snow_block
setblock ~4 ~14 ~10 minecraft:snow_block
setblock ~-9 ~8 ~-12 minecraft:snow_block
setblock ~6 ~11 ~8 minecraft:snow_block
setblock ~-6 ~7 ~-13 minecraft:snow_block
setblock ~-7 ~2 ~0 minecraft:snow_block
setblock ~3 ~22 ~11 minecraft:snow_block
setblock ~-5 ~7 ~-14 minecraft:snow_block
setblock ~-3 ~8 ~18 minecraft:snow_block
setblock ~-8 ~24 ~-2 minecraft:snow_block
setblock ~-7 ~7 ~-13 minecraft:snow_block
setblock ~-4 ~6 ~-14 minecraft:snow_block
setblock ~-8 ~23 ~-3 minecraft:snow_block
setblock ~-4 ~7 ~-14 minecraft:snow_block
setblock ~-11 ~10 ~-8 minecraft:snow_block
setblock ~-1 ~6 ~-14 minecraft:snow_block
setblock ~-10 ~15 ~4 minecraft:snow_block
setblock ~2 ~5 ~-13 minecraft:snow_block
setblock ~-3 ~22 ~-9 minecraft:snow_block
setblock ~-5 ~10 ~15 minecraft:snow_block
setblock ~4 ~26 ~5 minecraft:snow_block
setblock ~-11 ~17 ~-5 minecraft:snow_block
setblock ~1 ~8 ~1 minecraft:snow_block
setblock ~3 ~13 ~-14 minecraft:snow_block
setblock ~0 ~4 ~-1 minecraft:snow_block
setblock ~-1 ~7 ~-14 minecraft:snow_block
setblock ~-5 ~7 ~15 minecraft:snow_block
setblock ~-8 ~14 ~10 minecraft:snow_block
setblock ~-8 ~4 ~-10 minecraft:snow_block
setblock ~4 ~5 ~12 minecraft:snow_block
setblock ~-7 ~4 ~-11 minecraft:snow_block
setblock ~-9 ~5 ~-9 minecraft:snow_block
setblock ~-5 ~6 ~20 minecraft:snow_block
setblock ~-5 ~4 ~-12 minecraft:snow_block
setblock ~-3 ~20 ~10 minecraft:snow_block
setblock ~7 ~2 ~10 minecraft:snow_block
setblock ~8 ~8 ~6 minecraft:snow_block
setblock ~-9 ~3 ~2 minecraft:snow_block
setblock ~7 ~3 ~-9 minecraft:snow_block
setblock ~-6 ~5 ~-12 minecraft:snow_block
setblock ~-6 ~13 ~13 minecraft:snow_block
setblock ~0 ~10 ~-15 minecraft:snow_block
setblock ~4 ~6 ~13 minecraft:snow_block
setblock ~-2 ~6 ~22 minecraft:snow_block
setblock ~6 ~5 ~14 minecraft:snow_block
setblock ~-7 ~25 ~3 minecraft:snow_block
setblock ~-4 ~4 ~-12 minecraft:snow_block
setblock ~-6 ~0 ~-6 minecraft:snow_block
setblock ~3 ~9 ~12 minecraft:snow_block
setblock ~-4 ~5 ~-13 minecraft:snow_block
setblock ~7 ~12 ~-13 minecraft:snow_block
setblock ~5 ~3 ~13 minecraft:snow_block
setblock ~-4 ~4 ~-13 minecraft:snow_block
setblock ~-6 ~15 ~-13 minecraft:snow_block
setblock ~-11 ~17 ~-4 minecraft:snow_block
setblock ~-11 ~18 ~-4 minecraft:snow_block
setblock ~7 ~5 ~10 minecraft:snow_block
setblock ~-1 ~14 ~18 minecraft:blue_wool
setblock ~-10 ~15 ~-9 minecraft:snow_block
setblock ~-10 ~17 ~-9 minecraft:snow_block
setblock ~6 ~5 ~10 minecraft:snow_block
setblock ~6 ~7 ~7 minecraft:snow_block
setblock ~-9 ~23 ~5 minecraft:snow_block
setblock ~7 ~16 ~-12 minecraft:snow_block
setblock ~-5 ~6 ~12 minecraft:snow_block
setblock ~-10 ~16 ~-10 minecraft:snow_block
setblock ~-6 ~25 ~-2 minecraft:snow_block
setblock ~-3 ~7 ~21 minecraft:blue_wool
setblock ~-8 ~14 ~-13 minecraft:snow_block
setblock ~-2 ~1 ~-10 minecraft:snow_block
setblock ~-6 ~13 ~-13 minecraft:snow_block
setblock ~9 ~19 ~2 minecraft:snow_block
setblock ~4 ~5 ~20 minecraft:snow_block
setblock ~-11 ~15 ~-5 minecraft:snow_block
setblock ~-6 ~0 ~-7 minecraft:snow_block
setblock ~-6 ~12 ~12 minecraft:snow_block
setblock ~-10 ~18 ~-5 minecraft:snow_block
setblock ~9 ~6 ~-1 minecraft:snow_block
setblock ~-11 ~14 ~-4 minecraft:snow_block
setblock ~3 ~4 ~4 minecraft:snow_block
setblock ~-11 ~15 ~2 minecraft:snow_block
setblock ~-11 ~13 ~-2 minecraft:snow_block
setblock ~2 ~4 ~-12 minecraft:snow_block
setblock ~-11 ~13 ~-3 minecraft:snow_block
setblock ~-11 ~12 ~-3 minecraft:snow_block
setblock ~9 ~13 ~11 minecraft:snow_block
setblock ~10 ~12 ~10 minecraft:snow_block
setblock ~0 ~1 ~-10 minecraft:snow_block
setblock ~-10 ~16 ~4 minecraft:snow_block
setblock ~-11 ~11 ~-2 minecraft:snow_block
setblock ~-11 ~11 ~-3 minecraft:snow_block
setblock ~-1 ~12 ~16 minecraft:snow_block
setblock ~4 ~11 ~13 minecraft:snow_block
setblock ~-4 ~22 ~-8 minecraft:snow_block
setblock ~-11 ~10 ~-2 minecraft:snow_block
setblock ~-4 ~10 ~19 minecraft:snow_block
setblock ~5 ~6 ~17 minecraft:snow_block
setblock ~1 ~14 ~17 minecraft:blue_wool
setblock ~-6 ~24 ~-4 minecraft:snow_block
setblock ~-11 ~13 ~-6 minecraft:snow_block
setblock ~7 ~4 ~12 minecraft:snow_block
setblock ~10 ~18 ~-2 minecraft:snow_block
setblock ~4 ~6 ~18 minecraft:blue_wool
setblock ~-4 ~26 ~3 minecraft:snow_block
setblock ~5 ~4 ~-11 minecraft:snow_block
setblock ~10 ~8 ~-2 minecraft:snow_block
setblock ~-8 ~3 ~10 minecraft:snow_block
setblock ~-7 ~14 ~10 minecraft:snow_block
setblock ~-4 ~15 ~15 minecraft:snow_block
setblock ~-10 ~15 ~-8 minecraft:snow_block
setblock ~-10 ~12 ~-9 minecraft:snow_block
setblock ~-8 ~5 ~8 minecraft:snow_block
setblock ~-4 ~6 ~-13 minecraft:snow_block
setblock ~-8 ~2 ~10 minecraft:snow_block
setblock ~-4 ~9 ~19 minecraft:snow_block
setblock ~4 ~10 ~15 minecraft:snow_block
setblock ~9 ~5 ~-9 minecraft:snow_block
setblock ~-8 ~22 ~8 minecraft:snow_block
setblock ~3 ~8 ~17 minecraft:blue_wool
setblock ~-10 ~10 ~-10 minecraft:snow_block
setblock ~-7 ~6 ~8 minecraft:snow_block
setblock ~-11 ~15 ~-7 minecraft:snow_block
setblock ~1 ~22 ~12 minecraft:snow_block
setblock ~2 ~19 ~10 minecraft:snow_block
setblock ~8 ~11 ~-11 minecraft:snow_block
setblock ~-3 ~5 ~0 minecraft:snow_block
setblock ~-3 ~27 ~1 minecraft:snow_block
setblock ~-10 ~8 ~-8 minecraft:snow_block
setblock ~9 ~13 ~-10 minecraft:snow_block
setblock ~-3 ~9 ~17 minecraft:snow_block
setblock ~-10 ~9 ~-8 minecraft:snow_block
setblock ~5 ~1 ~-9 minecraft:snow_block
setblock ~1 ~4 ~-12 minecraft:snow_block
setblock ~-4 ~5 ~19 minecraft:snow_block
setblock ~-11 ~18 ~-3 minecraft:snow_block
setblock ~-10 ~7 ~-9 minecraft:snow_block
setblock ~0 ~26 ~5 minecraft:snow_block
setblock ~-11 ~13 ~1 minecraft:snow_block
setblock ~-5 ~9 ~15 minecraft:snow_block
setblock ~8 ~8 ~5 minecraft:snow_block
setblock ~10 ~16 ~-7 minecraft:snow_block
setblock ~-11 ~10 ~-5 minecraft:snow_block
setblock ~-10 ~20 ~-4 minecraft:snow_block
setblock ~-4 ~7 ~21 minecraft:snow_block
setblock ~-11 ~11 ~-7 minecraft:snow_block
setblock ~10 ~10 ~-5 minecraft:snow_block
setblock ~-11 ~12 ~-4 minecraft:snow_block
setblock ~-11 ~12 ~-5 minecraft:snow_block
setblock ~-10 ~7 ~-8 minecraft:snow_block
setblock ~-11 ~12 ~-2 minecraft:snow_block
setblock ~-9 ~6 ~1 minecraft:snow_block
setblock ~-8 ~5 ~9 minecraft:snow_block
setblock ~-11 ~10 ~-4 minecraft:snow_block
setblock ~-10 ~5 ~-6 minecraft:snow_block
setblock ~-10 ~5 ~-7 minecraft:snow_block
setblock ~-10 ~6 ~-8 minecraft:snow_block
setblock ~-5 ~10 ~9 minecraft:snow_block
setblock ~-10 ~5 ~-8 minecraft:snow_block
setblock ~-2 ~13 ~12 minecraft:snow_block
setblock ~-5 ~5 ~-12 minecraft:snow_block
setblock ~2 ~20 ~-11 minecraft:snow_block
setblock ~-10 ~8 ~-7 minecraft:snow_block
setblock ~10 ~10 ~-6 minecraft:snow_block
setblock ~-10 ~5 ~-9 minecraft:snow_block
setblock ~-4 ~9 ~17 minecraft:blue_wool
setblock ~-11 ~9 ~2 minecraft:snow_block
setblock ~9 ~3 ~-6 minecraft:snow_block
setblock ~-11 ~9 ~-1 minecraft:snow_block
setblock ~5 ~23 ~-5 minecraft:snow_block
setblock ~-3 ~17 ~8 minecraft:snow_block
setblock ~3 ~14 ~12 minecraft:snow_block
setblock ~-11 ~9 ~-2 minecraft:snow_block
setblock ~5 ~21 ~-9 minecraft:snow_block
setblock ~9 ~5 ~-4 minecraft:snow_block
setblock ~-3 ~17 ~9 minecraft:snow_block
setblock ~-11 ~9 ~-3 minecraft:snow_block
setblock ~-10 ~20 ~-2 minecraft:snow_block
setblock ~-11 ~8 ~-3 minecraft:snow_block
setblock ~-11 ~7 ~-4 minecraft:snow_block
setblock ~7 ~7 ~-12 minecraft:snow_block
setblock ~9 ~15 ~4 minecraft:snow_block
setblock ~-10 ~7 ~-5 minecraft:snow_block
setblock ~-8 ~9 ~4 minecraft:snow_block
setblock ~-10 ~7 ~-6 minecraft:snow_block
setblock ~-4 ~8 ~6 minecraft:snow_block
setblock ~-8 ~13 ~-13 minecraft:snow_block
setblock ~-10 ~6 ~-5 minecraft:snow_block
setblock ~-11 ~9 ~-5 minecraft:snow_block
setblock ~-10 ~8 ~-5 minecraft:snow_block
setblock ~-11 ~8 ~-4 minecraft:snow_block
setblock ~-4 ~10 ~-14 minecraft:snow_block
setblock ~-11 ~8 ~2 minecraft:snow_block
setblock ~8 ~20 ~8 minecraft:snow_block
setblock ~-5 ~20 ~9 minecraft:snow_block
setblock ~6 ~10 ~-13 minecraft:snow_block
setblock ~-11 ~7 ~1 minecraft:snow_block
setblock ~-5 ~5 ~13 minecraft:snow_block
setblock ~-10 ~4 ~-4 minecraft:snow_block
setblock ~-10 ~3 ~-5 minecraft:snow_block
setblock ~-10 ~3 ~-6 minecraft:snow_block
setblock ~-11 ~11 ~-1 minecraft:snow_block
setblock ~-10 ~4 ~-7 minecraft:snow_block
setblock ~-8 ~2 ~-8 minecraft:snow_block
setblock ~3 ~15 ~10 minecraft:snow_block
setblock ~-7 ~3 ~14 minecraft:snow_block
setblock ~-9 ~2 ~0 minecraft:snow_block
setblock ~2 ~26 ~4 minecraft:snow_block
setblock ~2 ~1 ~-1 minecraft:snow_block
setblock ~-8 ~3 ~-10 minecraft:snow_block
setblock ~-7 ~9 ~8 minecraft:snow_block
setblock ~2 ~24 ~9 minecraft:snow_block
setblock ~7 ~21 ~7 minecraft:snow_block
setblock ~-10 ~3 ~-2 minecraft:snow_block
setblock ~2 ~18 ~10 minecraft:snow_block
setblock ~-8 ~18 ~7 minecraft:snow_block
setblock ~1 ~7 ~6 minecraft:snow_block
setblock ~-7 ~2 ~-9 minecraft:snow_block
setblock ~0 ~21 ~-11 minecraft:snow_block
setblock ~-10 ~9 ~5 minecraft:snow_block
setblock ~0 ~27 ~4 minecraft:snow_block
setblock ~4 ~26 ~3 minecraft:snow_block
setblock ~0 ~13 ~11 minecraft:snow_block
setblock ~-6 ~1 ~-9 minecraft:snow_block
setblock ~9 ~12 ~-9 minecraft:snow_block
setblock ~-5 ~1 ~-9 minecraft:snow_block
setblock ~-8 ~11 ~7 minecraft:snow_block
setblock ~-8 ~19 ~-9 minecraft:snow_block
setblock ~-10 ~4 ~-1 minecraft:snow_block
setblock ~5 ~4 ~-12 minecraft:snow_block
setblock ~-4 ~1 ~-9 minecraft:snow_block
setblock ~3 ~13 ~17 minecraft:snow_block
setblock ~1 ~19 ~12 minecraft:snow_block
setblock ~10 ~10 ~0 minecraft:snow_block
setblock ~5 ~5 ~10 minecraft:snow_block
setblock ~-3 ~3 ~-11 minecraft:snow_block
setblock ~-1 ~2 ~-11 minecraft:snow_block
setblock ~-2 ~18 ~13 minecraft:blue_wool
setblock ~1 ~7 ~2 minecraft:snow_block
setblock ~-1 ~3 ~-11 minecraft:snow_block
setblock ~3 ~10 ~9 minecraft:snow_block
setblock ~-9 ~22 ~5 minecraft:snow_block
setblock ~-1 ~8 ~21 minecraft:blue_wool
setblock ~-8 ~1 ~-5 minecraft:snow_block
setblock ~1 ~17 ~14 minecraft:blue_wool
setblock ~1 ~25 ~-4 minecraft:snow_block
setblock ~-7 ~0 ~-6 minecraft:snow_block
setblock ~0 ~18 ~13 minecraft:snow_block
setblock ~-5 ~0 ~-8 minecraft:snow_block
setblock ~2 ~12 ~-15 minecraft:snow_block
setblock ~5 ~5 ~17 minecraft:blue_wool
setblock ~7 ~23 ~5 minecraft:snow_block
setblock ~-3 ~1 ~-9 minecraft:snow_block
setblock ~-4 ~0 ~-5 minecraft:snow_block
setblock ~9 ~18 ~-5 minecraft:snow_block
setblock ~8 ~22 ~4 minecraft:snow_block
setblock ~1 ~13 ~13 minecraft:snow_block
setblock ~-4 ~0 ~-6 minecraft:snow_block
setblock ~-3 ~26 ~5 minecraft:snow_block
setblock ~0 ~20 ~-11 minecraft:snow_block
setblock ~-11 ~5 ~-2 minecraft:snow_block
setblock ~-1 ~0 ~-8 minecraft:snow_block
setblock ~1 ~17 ~13 minecraft:blue_wool
setblock ~-1 ~0 ~-9 minecraft:snow_block
setblock ~9 ~19 ~-7 minecraft:snow_block
setblock ~6 ~9 ~10 minecraft:snow_block
setblock ~-11 ~14 ~3 minecraft:snow_block
setblock ~-11 ~20 ~0 minecraft:snow_block
setblock ~6 ~24 ~5 minecraft:snow_block
setblock ~3 ~20 ~-10 minecraft:snow_block
setblock ~9 ~20 ~-3 minecraft:snow_block
setblock ~-10 ~15 ~-10 minecraft:snow_block
setblock ~-2 ~0 ~-5 minecraft:snow_block
setblock ~-11 ~11 ~-4 minecraft:snow_block
setblock ~8 ~12 ~-11 minecraft:snow_block
setblock ~-8 ~20 ~-8 minecraft:snow_block
setblock ~1 ~9 ~8 minecraft:snow_block
setblock ~6 ~1 ~-7 minecraft:snow_block
setblock ~1 ~24 ~9 minecraft:snow_block
setblock ~-1 ~0 ~-7 minecraft:snow_block
setblock ~4 ~7 ~13 minecraft:snow_block
setblock ~-10 ~8 ~4 minecraft:snow_block
setblock ~-11 ~7 ~-3 minecraft:snow_block
setblock ~7 ~25 ~2 minecraft:snow_block
setblock ~-3 ~4 ~4 minecraft:snow_block
setblock ~-10 ~5 ~-2 minecraft:snow_block
setblock ~3 ~26 ~-1 minecraft:snow_block
setblock ~-10 ~4 ~-3 minecraft:snow_block
setblock ~2 ~15 ~16 minecraft:snow_block
setblock ~-10 ~8 ~3 minecraft:snow_block
setblock ~10 ~12 ~8 minecraft:snow_block
setblock ~-10 ~3 ~-3 minecraft:snow_block
setblock ~-6 ~10 ~7 minecraft:snow_block
setblock ~-1 ~0 ~-3 minecraft:snow_block
setblock ~-10 ~21 ~1 minecraft:snow_block
setblock ~-2 ~0 ~-3 minecraft:snow_block
setblock ~-10 ~4 ~1 minecraft:snow_block
setblock ~9 ~18 ~5 minecraft:snow_block
setblock ~5 ~11 ~9 minecraft:snow_block
setblock ~-3 ~0 ~-2 minecraft:snow_block
setblock ~4 ~6 ~19 minecraft:blue_wool
setblock ~6 ~12 ~13 minecraft:snow_block
setblock ~4 ~10 ~11 minecraft:snow_block
setblock ~-2 ~19 ~-12 minecraft:snow_block
setblock ~3 ~9 ~-14 minecraft:snow_block
setblock ~-9 ~17 ~-9 minecraft:snow_block
setblock ~-5 ~21 ~-9 minecraft:snow_block
setblock ~-4 ~0 ~-3 minecraft:snow_block
setblock ~9 ~11 ~8 minecraft:snow_block
setblock ~-3 ~0 ~-4 minecraft:snow_block
setblock ~-10 ~16 ~-7 minecraft:snow_block
setblock ~-9 ~1 ~-4 minecraft:snow_block
setblock ~-4 ~0 ~-4 minecraft:snow_block
setblock ~-7 ~0 ~-3 minecraft:snow_block
setblock ~-4 ~26 ~0 minecraft:snow_block
setblock ~-9 ~16 ~9 minecraft:snow_block
setblock ~6 ~21 ~9 minecraft:snow_block
setblock ~8 ~14 ~7 minecraft:snow_block
setblock ~7 ~8 ~9 minecraft:snow_block
setblock ~-5 ~0 ~-4 minecraft:snow_block
setblock ~1 ~10 ~20 minecraft:snow_block
setblock ~6 ~23 ~7 minecraft:snow_block
setblock ~5 ~25 ~-3 minecraft:snow_block
setblock ~-5 ~0 ~-2 minecraft:snow_block
setblock ~5 ~8 ~15 minecraft:snow_block
setblock ~6 ~19 ~9 minecraft:snow_block
setblock ~8 ~9 ~5 minecraft:snow_block
setblock ~-4 ~0 ~-2 minecraft:snow_block
setblock ~0 ~13 ~16 minecraft:blue_wool
setblock ~3 ~9 ~7 minecraft:snow_block
setblock ~-1 ~17 ~13 minecraft:blue_wool
setblock ~-2 ~2 ~-1 minecraft:snow_block
setblock ~-11 ~8 ~-5 minecraft:snow_block
setblock ~-8 ~0 ~-4 minecraft:snow_block
setblock ~-9 ~1 ~-3 minecraft:snow_block
setblock ~-8 ~1 ~-2 minecraft:snow_block
setblock ~2 ~18 ~-12 minecraft:snow_block
setblock ~5 ~25 ~3 minecraft:snow_block
setblock ~-11 ~15 ~-6 minecraft:snow_block
setblock ~-9 ~18 ~5 minecraft:snow_block
setblock ~10 ~5 ~-2 minecraft:snow_block
setblock ~-10 ~4 ~0 minecraft:snow_block
setblock ~-9 ~5 ~1 minecraft:snow_block
setblock ~6 ~7 ~14 minecraft:snow_block
setblock ~-6 ~6 ~19 minecraft:snow_block
setblock ~7 ~1 ~-7 minecraft:snow_block
setblock ~-4 ~10 ~10 minecraft:snow_block
setblock ~1 ~19 ~11 minecraft:snow_block
setblock ~-9 ~8 ~6 minecraft:snow_block
setblock ~-8 ~3 ~13 minecraft:snow_block
setblock ~-3 ~7 ~5 minecraft:snow_block
setblock ~7 ~6 ~9 minecraft:snow_block
setblock ~-10 ~6 ~1 minecraft:snow_block
setblock ~-10 ~4 ~-6 minecraft:snow_block
setblock ~-9 ~8 ~3 minecraft:snow_block
setblock ~-7 ~1 ~-1 minecraft:snow_block
setblock ~2 ~13 ~-14 minecraft:snow_block
setblock ~-6 ~1 ~-1 minecraft:snow_block
setblock ~-7 ~19 ~-10 minecraft:snow_block
setblock ~-7 ~2 ~-1 minecraft:snow_block
setblock ~9 ~19 ~1 minecraft:snow_block
setblock ~-9 ~3 ~1 minecraft:snow_block
setblock ~-8 ~7 ~-12 minecraft:snow_block
setblock ~6 ~14 ~9 minecraft:snow_block
setblock ~3 ~3 ~1 minecraft:snow_block
setblock ~7 ~14 ~11 minecraft:snow_block
setblock ~-5 ~9 ~17 minecraft:snow_block
setblock ~-9 ~7 ~3 minecraft:snow_block
setblock ~3 ~3 ~2 minecraft:snow_block
setblock ~0 ~11 ~-15 minecraft:snow_block
setblock ~5 ~24 ~7 minecraft:snow_block
setblock ~-3 ~5 ~1 minecraft:snow_block
setblock ~-11 ~11 ~8 minecraft:snow_block
setblock ~4 ~10 ~10 minecraft:snow_block
setblock ~-7 ~3 ~3 minecraft:snow_block
setblock ~7 ~8 ~7 minecraft:snow_block
setblock ~1 ~19 ~15 minecraft:snow_block
setblock ~-1 ~3 ~-12 minecraft:snow_block
setblock ~-8 ~6 ~3 minecraft:snow_block
setblock ~10 ~17 ~-6 minecraft:snow_block
setblock ~1 ~13 ~17 minecraft:blue_wool
setblock ~-4 ~13 ~17 minecraft:snow_block
setblock ~-9 ~13 ~6 minecraft:snow_block
setblock ~-3 ~6 ~3 minecraft:snow_block
setblock ~-2 ~11 ~18 minecraft:snow_block
setblock ~-2 ~14 ~17 minecraft:blue_wool
setblock ~-6 ~20 ~-9 minecraft:snow_block
setblock ~-5 ~10 ~-14 minecraft:snow_block
setblock ~-10 ~11 ~11 minecraft:snow_block
setblock ~5 ~14 ~9 minecraft:snow_block
setblock ~4 ~24 ~-5 minecraft:snow_block
setblock ~-8 ~11 ~10 minecraft:snow_block
setblock ~-1 ~13 ~13 minecraft:snow_block
setblock ~-1 ~16 ~13 minecraft:snow_block
setblock ~-7 ~11 ~7 minecraft:snow_block
setblock ~-7 ~11 ~6 minecraft:snow_block
setblock ~-8 ~12 ~8 minecraft:snow_block
setblock ~7 ~22 ~-4 minecraft:snow_block
setblock ~3 ~8 ~20 minecraft:snow_block
setblock ~-5 ~11 ~11 minecraft:snow_block
setblock ~7 ~11 ~12 minecraft:snow_block
setblock ~-5 ~10 ~10 minecraft:snow_block
setblock ~3 ~3 ~-12 minecraft:snow_block
setblock ~6 ~14 ~12 minecraft:snow_block
setblock ~-5 ~11 ~9 minecraft:snow_block
setblock ~-10 ~19 ~-4 minecraft:snow_block
setblock ~-3 ~10 ~11 minecraft:snow_block
setblock ~-9 ~21 ~6 minecraft:snow_block
setblock ~-7 ~12 ~13 minecraft:snow_block
setblock ~8 ~17 ~-9 minecraft:snow_block
setblock ~4 ~0 ~-4 minecraft:snow_block
setblock ~-8 ~7 ~7 minecraft:snow_block
setblock ~-1 ~10 ~10 minecraft:snow_block
setblock ~2 ~7 ~6 minecraft:snow_block
setblock ~4 ~15 ~8 minecraft:snow_block
setblock ~-10 ~10 ~7 minecraft:snow_block
setblock ~7 ~4 ~13 minecraft:snow_block
setblock ~-1 ~10 ~9 minecraft:snow_block
setblock ~0 ~9 ~8 minecraft:snow_block
setblock ~4 ~9 ~5 minecraft:snow_block
setblock ~-3 ~23 ~-8 minecraft:snow_block
setblock ~0 ~8 ~2 minecraft:snow_block
setblock ~-2 ~10 ~9 minecraft:snow_block
setblock ~-2 ~9 ~7 minecraft:snow_block
setblock ~-6 ~11 ~12 minecraft:snow_block
setblock ~-3 ~9 ~12 minecraft:snow_block
setblock ~1 ~14 ~12 minecraft:snow_block
setblock ~-3 ~10 ~13 minecraft:snow_block
setblock ~-3 ~11 ~14 minecraft:snow_block
setblock ~10 ~14 ~-1 minecraft:snow_block
setblock ~2 ~8 ~16 minecraft:snow_block
setblock ~5 ~22 ~-8 minecraft:snow_block
setblock ~-1 ~0 ~-5 minecraft:snow_block
setblock ~2 ~7 ~5 minecraft:snow_block
setblock ~-9 ~2 ~-3 minecraft:snow_block
setblock ~-2 ~12 ~16 minecraft:snow_block
setblock ~-1 ~12 ~15 minecraft:snow_block
setblock ~-2 ~10 ~12 minecraft:snow_block
setblock ~10 ~9 ~3 minecraft:snow_block
setblock ~4 ~4 ~17 minecraft:snow_block
setblock ~4 ~10 ~16 minecraft:snow_block
setblock ~-9 ~4 ~-7 minecraft:snow_block
setblock ~6 ~11 ~-13 minecraft:snow_block
setblock ~-1 ~11 ~12 minecraft:snow_block
setblock ~0 ~5 ~-13 minecraft:snow_block
setblock ~-4 ~11 ~18 minecraft:snow_block
setblock ~-1 ~13 ~16 minecraft:blue_wool
setblock ~1 ~15 ~16 minecraft:snow_block
setblock ~-1 ~10 ~11 minecraft:snow_block
setblock ~-6 ~10 ~6 minecraft:snow_block
setblock ~-9 ~19 ~5 minecraft:snow_block
setblock ~8 ~5 ~1 minecraft:snow_block
setblock ~0 ~26 ~7 minecraft:snow_block
setblock ~-5 ~10 ~7 minecraft:snow_block
setblock ~-4 ~7 ~5 minecraft:snow_block
setblock ~4 ~18 ~9 minecraft:snow_block
setblock ~-3 ~10 ~8 minecraft:snow_block
setblock ~9 ~6 ~-9 minecraft:snow_block
setblock ~-3 ~24 ~-5 minecraft:snow_block
setblock ~-4 ~11 ~17 minecraft:blue_wool
setblock ~4 ~19 ~9 minecraft:snow_block
setblock ~-10 ~12 ~-10 minecraft:snow_block
setblock ~-3 ~9 ~8 minecraft:snow_block
setblock ~-1 ~13 ~12 minecraft:blue_wool
setblock ~4 ~26 ~-2 minecraft:snow_block
setblock ~9 ~7 ~-10 minecraft:snow_block
setblock ~-7 ~14 ~9 minecraft:snow_block
setblock ~-5 ~10 ~6 minecraft:snow_block
setblock ~-6 ~3 ~14 minecraft:snow_block
setblock ~-8 ~8 ~7 minecraft:snow_block
setblock ~-3 ~9 ~6 minecraft:snow_block
setblock ~-8 ~5 ~3 minecraft:snow_block
setblock ~-7 ~8 ~4 minecraft:snow_block
setblock ~-7 ~7 ~4 minecraft:snow_block
setblock ~-1 ~9 ~9 minecraft:snow_block
setblock ~5 ~5 ~11 minecraft:snow_block
setblock ~-8 ~3 ~2 minecraft:snow_block
setblock ~-2 ~16 ~16 minecraft:snow_block
setblock ~-7 ~3 ~1 minecraft:snow_block
setblock ~10 ~8 ~0 minecraft:snow_block
setblock ~8 ~9 ~4 minecraft:snow_block
setblock ~7 ~4 ~-10 minecraft:snow_block
setblock ~10 ~10 ~7 minecraft:snow_block
setblock ~9 ~19 ~-5 minecraft:snow_block
setblock ~-10 ~9 ~-7 minecraft:snow_block
setblock ~10 ~13 ~0 minecraft:snow_block
setblock ~1 ~12 ~-15 minecraft:snow_block
setblock ~3 ~26 ~5 minecraft:snow_block
setblock ~-5 ~10 ~8 minecraft:snow_block
setblock ~-2 ~13 ~15 minecraft:snow_block
setblock ~7 ~7 ~8 minecraft:snow_block
setblock ~-1 ~1 ~-2 minecraft:snow_block
setblock ~-3 ~2 ~0 minecraft:snow_block
setblock ~1 ~7 ~5 minecraft:snow_block
setblock ~-3 ~6 ~5 minecraft:snow_block
setblock ~1 ~12 ~20 minecraft:snow_block
setblock ~9 ~6 ~-4 minecraft:snow_block
setblock ~-1 ~14 ~11 minecraft:snow_block
setblock ~-2 ~16 ~14 minecraft:snow_block
setblock ~8 ~15 ~7 minecraft:snow_block
setblock ~-6 ~1 ~-2 minecraft:snow_block
setblock ~8 ~11 ~6 minecraft:snow_block
setblock ~1 ~12 ~17 minecraft:snow_block
setblock ~3 ~20 ~-11 minecraft:snow_block
setblock ~-5 ~1 ~-2 minecraft:snow_block
setblock ~-6 ~2 ~0 minecraft:snow_block
setblock ~4 ~19 ~-11 minecraft:snow_block
setblock ~1 ~14 ~-14 minecraft:snow_block
setblock ~4 ~0 ~-5 minecraft:snow_block
setblock ~-5 ~3 ~1 minecraft:snow_block
setblock ~10 ~11 ~-1 minecraft:snow_block
setblock ~-5 ~4 ~3 minecraft:snow_block
setblock ~-1 ~12 ~13 minecraft:blue_wool
setblock ~-4 ~18 ~8 minecraft:snow_block
setblock ~-4 ~2 ~0 minecraft:snow_block
setblock ~1 ~12 ~16 minecraft:snow_block
setblock ~8 ~14 ~-12 minecraft:snow_block
setblock ~7 ~12 ~8 minecraft:snow_block
setblock ~3 ~10 ~14 minecraft:blue_wool
setblock ~1 ~7 ~20 minecraft:snow_block
setblock ~7 ~16 ~9 minecraft:snow_block
setblock ~-2 ~10 ~8 minecraft:snow_block
setblock ~-5 ~26 ~5 minecraft:snow_block
setblock ~-5 ~4 ~4 minecraft:snow_block
setblock ~0 ~0 ~-3 minecraft:snow_block
setblock ~9 ~14 ~-8 minecraft:snow_block
setblock ~5 ~0 ~-3 minecraft:snow_block
setblock ~-6 ~4 ~4 minecraft:snow_block
setblock ~-2 ~2 ~0 minecraft:snow_block
setblock ~-3 ~4 ~1 minecraft:snow_block
setblock ~-3 ~5 ~2 minecraft:snow_block
setblock ~-11 ~13 ~-4 minecraft:snow_block
setblock ~9 ~22 ~3 minecraft:snow_block
setblock ~9 ~21 ~1 minecraft:snow_block
setblock ~6 ~17 ~-12 minecraft:snow_block
setblock ~-6 ~15 ~13 minecraft:snow_block
setblock ~-3 ~4 ~2 minecraft:snow_block
setblock ~-2 ~0 ~-7 minecraft:snow_block
setblock ~-8 ~3 ~-9 minecraft:snow_block
setblock ~-11 ~8 ~0 minecraft:snow_block
setblock ~-9 ~7 ~2 minecraft:snow_block
setblock ~-3 ~0 ~-5 minecraft:snow_block
setblock ~3 ~22 ~-8 minecraft:snow_block
setblock ~2 ~15 ~10 minecraft:snow_block
setblock ~-2 ~6 ~-1 minecraft:snow_block
setblock ~1 ~16 ~12 minecraft:snow_block
setblock ~-3 ~6 ~0 minecraft:snow_block
setblock ~-3 ~6 ~2 minecraft:snow_block
setblock ~-2 ~7 ~-1 minecraft:snow_block
setblock ~2 ~4 ~-13 minecraft:snow_block
setblock ~-2 ~8 ~1 minecraft:snow_block
setblock ~-1 ~8 ~0 minecraft:snow_block
setblock ~3 ~18 ~8 minecraft:snow_block
setblock ~-5 ~9 ~6 minecraft:snow_block
setblock ~9 ~11 ~9 minecraft:snow_block
setblock ~-3 ~10 ~10 minecraft:snow_block
setblock ~10 ~10 ~5 minecraft:snow_block
setblock ~-6 ~9 ~5 minecraft:snow_block
setblock ~-6 ~8 ~4 minecraft:snow_block
setblock ~8 ~17 ~5 minecraft:snow_block
setblock ~-4 ~8 ~5 minecraft:snow_block
setblock ~8 ~16 ~-10 minecraft:snow_block
setblock ~-2 ~19 ~12 minecraft:snow_block
setblock ~9 ~7 ~-9 minecraft:snow_block
setblock ~1 ~2 ~-11 minecraft:snow_block
setblock ~-3 ~0 ~-3 minecraft:snow_block
setblock ~-4 ~7 ~4 minecraft:snow_block
setblock ~-10 ~11 ~-10 minecraft:snow_block
setblock ~-11 ~7 ~0 minecraft:snow_block
setblock ~-6 ~6 ~4 minecraft:snow_block
setblock ~-5 ~6 ~4 minecraft:snow_block
setblock ~1 ~18 ~13 minecraft:blue_wool
setblock ~4 ~4 ~18 minecraft:snow_block
setblock ~1 ~27 ~2 minecraft:snow_block
setblock ~2 ~18 ~-13 minecraft:snow_block
setblock ~-2 ~6 ~5 minecraft:snow_block
setblock ~-3 ~5 ~5 minecraft:snow_block
setblock ~5 ~10 ~7 minecraft:snow_block
setblock ~-9 ~15 ~11 minecraft:snow_block
setblock ~0 ~25 ~9 minecraft:snow_block
setblock ~-4 ~5 ~5 minecraft:snow_block
setblock ~-4 ~4 ~4 minecraft:snow_block
setblock ~-9 ~5 ~-10 minecraft:snow_block
setblock ~6 ~23 ~-6 minecraft:snow_block
setblock ~-4 ~26 ~-3 minecraft:snow_block
setblock ~-10 ~11 ~6 minecraft:blue_wool
setblock ~-9 ~5 ~3 minecraft:snow_block
setblock ~10 ~10 ~-2 minecraft:snow_block
setblock ~-2 ~7 ~1 minecraft:snow_block
setblock ~-5 ~8 ~4 minecraft:snow_block
setblock ~-3 ~5 ~4 minecraft:snow_block
setblock ~-4 ~25 ~7 minecraft:snow_block
setblock ~-1 ~5 ~-1 minecraft:snow_block
setblock ~-8 ~2 ~0 minecraft:snow_block
setblock ~-1 ~15 ~17 minecraft:snow_block
setblock ~6 ~5 ~-12 minecraft:snow_block
setblock ~-7 ~4 ~9 minecraft:snow_block
setblock ~-10 ~9 ~4 minecraft:snow_block
setblock ~7 ~19 ~-8 minecraft:snow_block
setblock ~-2 ~14 ~16 minecraft:blue_wool
setblock ~-11 ~14 ~-5 minecraft:snow_block
setblock ~-2 ~19 ~14 minecraft:snow_block
setblock ~7 ~9 ~6 minecraft:snow_block
setblock ~-2 ~19 ~15 minecraft:snow_block
setblock ~-9 ~19 ~8 minecraft:snow_block
setblock ~-11 ~8 ~-1 minecraft:snow_block
setblock ~4 ~20 ~-11 minecraft:snow_block
setblock ~-7 ~5 ~-12 minecraft:snow_block
setblock ~0 ~10 ~9 minecraft:snow_block
setblock ~8 ~18 ~7 minecraft:snow_block
setblock ~-3 ~18 ~14 minecraft:snow_block
setblock ~7 ~16 ~-11 minecraft:snow_block
setblock ~1 ~14 ~18 minecraft:snow_block
setblock ~6 ~8 ~10 minecraft:snow_block
setblock ~-8 ~11 ~6 minecraft:snow_block
setblock ~-1 ~4 ~-12 minecraft:snow_block
setblock ~1 ~6 ~4 minecraft:snow_block
setblock ~-9 ~11 ~6 minecraft:snow_block
setblock ~-10 ~11 ~8 minecraft:snow_block
setblock ~-10 ~12 ~8 minecraft:snow_block
setblock ~8 ~23 ~0 minecraft:snow_block
setblock ~-9 ~12 ~9 minecraft:snow_block
setblock ~-1 ~10 ~19 minecraft:snow_block
setblock ~-9 ~11 ~9 minecraft:snow_block
setblock ~9 ~3 ~0 minecraft:snow_block
setblock ~-7 ~8 ~5 minecraft:snow_block
setblock ~9 ~12 ~11 minecraft:snow_block
setblock ~8 ~18 ~-9 minecraft:snow_block
setblock ~5 ~4 ~16 minecraft:snow_block
setblock ~0 ~0 ~-2 minecraft:snow_block
setblock ~-2 ~17 ~14 minecraft:blue_wool
setblock ~4 ~11 ~9 minecraft:snow_block
setblock ~-2 ~15 ~14 minecraft:snow_block
setblock ~8 ~4 ~1 minecraft:snow_block
setblock ~-7 ~2 ~-10 minecraft:snow_block
setblock ~8 ~4 ~2 minecraft:snow_block
setblock ~8 ~5 ~-10 minecraft:snow_block
setblock ~-2 ~21 ~12 minecraft:snow_block
setblock ~-9 ~2 ~-4 minecraft:snow_block
setblock ~-2 ~17 ~16 minecraft:snow_block
setblock ~10 ~7 ~-2 minecraft:snow_block
setblock ~9 ~8 ~-6 minecraft:snow_block
setblock ~-11 ~16 ~-4 minecraft:snow_block
setblock ~0 ~14 ~-15 minecraft:snow_block
setblock ~-2 ~17 ~13 minecraft:blue_wool
setblock ~8 ~12 ~7 minecraft:snow_block
setblock ~-11 ~9 ~3 minecraft:snow_block
setblock ~-2 ~15 ~13 minecraft:snow_block
setblock ~3 ~7 ~14 minecraft:snow_block
setblock ~8 ~7 ~-11 minecraft:snow_block
setblock ~-7 ~15 ~13 minecraft:snow_block
setblock ~7 ~13 ~13 minecraft:snow_block
setblock ~8 ~20 ~5 minecraft:snow_block
setblock ~-8 ~4 ~10 minecraft:snow_block
setblock ~6 ~14 ~10 minecraft:snow_block
setblock ~2 ~27 ~2 minecraft:snow_block
setblock ~-11 ~12 ~2 minecraft:snow_block
setblock ~9 ~17 ~-8 minecraft:snow_block
setblock ~10 ~12 ~-7 minecraft:snow_block
setblock ~-9 ~23 ~1 minecraft:snow_block
setblock ~-10 ~12 ~6 minecraft:snow_block
setblock ~7 ~10 ~10 minecraft:snow_block
setblock ~-5 ~10 ~16 minecraft:snow_block
setblock ~-2 ~14 ~12 minecraft:snow_block
setblock ~-8 ~3 ~11 minecraft:snow_block
setblock ~8 ~13 ~-12 minecraft:snow_block
setblock ~-10 ~11 ~9 minecraft:snow_block
setblock ~-1 ~13 ~11 minecraft:snow_block
setblock ~-2 ~15 ~12 minecraft:snow_block
setblock ~-10 ~12 ~10 minecraft:snow_block
setblock ~-3 ~25 ~7 minecraft:snow_block
setblock ~-2 ~13 ~13 minecraft:snow_block
setblock ~-3 ~18 ~10 minecraft:snow_block
setblock ~7 ~3 ~2 minecraft:snow_block
setblock ~-7 ~24 ~7 minecraft:snow_block
setblock ~-1 ~15 ~15 minecraft:snow_block
setblock ~-9 ~20 ~7 minecraft:snow_block
setblock ~-1 ~21 ~-11 minecraft:snow_block
setblock ~-6 ~6 ~11 minecraft:snow_block
setblock ~9 ~21 ~-3 minecraft:snow_block
setblock ~7 ~2 ~-8 minecraft:snow_block
setblock ~-1 ~12 ~12 minecraft:snow_block
setblock ~10 ~10 ~1 minecraft:snow_block
setblock ~7 ~5 ~8 minecraft:snow_block
setblock ~3 ~16 ~13 minecraft:snow_block
setblock ~-2 ~15 ~11 minecraft:snow_block
setblock ~-1 ~16 ~12 minecraft:snow_block
setblock ~8 ~4 ~-8 minecraft:snow_block
setblock ~-1 ~27 ~1 minecraft:snow_block
setblock ~-10 ~14 ~-8 minecraft:snow_block
setblock ~1 ~13 ~16 minecraft:snow_block
setblock ~0 ~12 ~15 minecraft:snow_block
setblock ~-1 ~27 ~0 minecraft:snow_block
setblock ~-5 ~10 ~12 minecraft:snow_block
setblock ~-7 ~15 ~14 minecraft:snow_block
setblock ~5 ~14 ~14 minecraft:snow_block
setblock ~5 ~2 ~-10 minecraft:snow_block
setblock ~-1 ~27 ~-1 minecraft:snow_block
setblock ~3 ~27 ~1 minecraft:snow_block
setblock ~0 ~5 ~-1 minecraft:snow_block
setblock ~-1 ~20 ~-11 minecraft:snow_block
setblock ~0 ~14 ~12 minecraft:snow_block
setblock ~-1 ~19 ~-12 minecraft:snow_block
setblock ~-6 ~8 ~12 minecraft:snow_block
setblock ~-2 ~20 ~-11 minecraft:snow_block
setblock ~-7 ~11 ~8 minecraft:snow_block
setblock ~-1 ~22 ~-9 minecraft:snow_block
setblock ~-9 ~21 ~4 minecraft:snow_block
setblock ~-1 ~15 ~18 minecraft:snow_block
setblock ~-1 ~14 ~-15 minecraft:snow_block
setblock ~3 ~7 ~4 minecraft:snow_block
setblock ~2 ~17 ~13 minecraft:blue_wool
setblock ~8 ~22 ~-4 minecraft:snow_block
setblock ~-2 ~7 ~3 minecraft:snow_block
setblock ~-2 ~14 ~-15 minecraft:snow_block
setblock ~0 ~8 ~-14 minecraft:snow_block
setblock ~-8 ~21 ~9 minecraft:snow_block
setblock ~-11 ~16 ~-7 minecraft:snow_block
setblock ~-1 ~9 ~7 minecraft:snow_block
setblock ~0 ~9 ~-14 minecraft:snow_block
setblock ~6 ~24 ~6 minecraft:snow_block
setblock ~-1 ~14 ~17 minecraft:blue_wool
setblock ~5 ~21 ~-8 minecraft:snow_block
setblock ~0 ~24 ~9 minecraft:snow_block
setblock ~-5 ~24 ~8 minecraft:snow_block
setblock ~-1 ~9 ~19 minecraft:snow_block
setblock ~0 ~22 ~11 minecraft:snow_block
setblock ~4 ~24 ~8 minecraft:snow_block
setblock ~10 ~14 ~1 minecraft:snow_block
setblock ~-1 ~4 ~0 minecraft:snow_block
setblock ~3 ~23 ~9 minecraft:snow_block
setblock ~-9 ~13 ~-12 minecraft:snow_block
setblock ~2 ~2 ~-11 minecraft:snow_block
setblock ~8 ~14 ~12 minecraft:snow_block
setblock ~-2 ~8 ~7 minecraft:snow_block
setblock ~-1 ~7 ~4 minecraft:snow_block
setblock ~4 ~9 ~17 minecraft:snow_block
setblock ~5 ~23 ~8 minecraft:snow_block
setblock ~-4 ~3 ~2 minecraft:snow_block
setblock ~5 ~24 ~8 minecraft:snow_block
setblock ~2 ~6 ~22 minecraft:snow_block
setblock ~6 ~21 ~10 minecraft:snow_block
setblock ~-8 ~7 ~8 minecraft:snow_block
setblock ~-6 ~2 ~-10 minecraft:snow_block
setblock ~7 ~22 ~8 minecraft:snow_block
setblock ~4 ~23 ~9 minecraft:snow_block
setblock ~4 ~25 ~7 minecraft:snow_block
setblock ~0 ~7 ~20 minecraft:snow_block
setblock ~-11 ~11 ~2 minecraft:snow_block
setblock ~0 ~2 ~-1 minecraft:snow_block
setblock ~4 ~24 ~7 minecraft:snow_block
setblock ~-9 ~2 ~-7 minecraft:snow_block
setblock ~2 ~26 ~0 minecraft:snow_block
setblock ~-5 ~7 ~20 minecraft:snow_block
setblock ~-6 ~25 ~-3 minecraft:snow_block
setblock ~1 ~8 ~-14 minecraft:snow_block
setblock ~-4 ~1 ~-1 minecraft:snow_block
setblock ~4 ~18 ~8 minecraft:snow_block
setblock ~1 ~26 ~7 minecraft:snow_block
setblock ~4 ~10 ~14 minecraft:blue_wool
setblock ~6 ~17 ~8 minecraft:snow_block
setblock ~-1 ~7 ~2 minecraft:snow_block
setblock ~8 ~7 ~3 minecraft:snow_block
setblock ~2 ~25 ~8 minecraft:snow_block
setblock ~4 ~12 ~14 minecraft:snow_block
setblock ~-6 ~10 ~14 minecraft:snow_block
setblock ~1 ~25 ~8 minecraft:snow_block
setblock ~0 ~25 ~8 minecraft:snow_block
setblock ~2 ~26 ~5 minecraft:snow_block
setblock ~-3 ~3 ~1 minecraft:snow_block
setblock ~3 ~26 ~-2 minecraft:snow_block
setblock ~6 ~6 ~-12 minecraft:snow_block
setblock ~5 ~25 ~5 minecraft:snow_block
setblock ~8 ~15 ~11 minecraft:snow_block
setblock ~-2 ~6 ~0 minecraft:snow_block
setblock ~9 ~16 ~-9 minecraft:snow_block
setblock ~1 ~17 ~12 minecraft:blue_wool
setblock ~-10 ~17 ~-8 minecraft:snow_block
setblock ~-2 ~6 ~3 minecraft:snow_block
setblock ~-6 ~19 ~-10 minecraft:snow_block
setblock ~-11 ~5 ~-3 minecraft:snow_block
setblock ~7 ~24 ~5 minecraft:snow_block
setblock ~7 ~20 ~10 minecraft:snow_block
setblock ~9 ~8 ~4 minecraft:snow_block
setblock ~10 ~15 ~-6 minecraft:snow_block
setblock ~4 ~23 ~8 minecraft:snow_block
setblock ~7 ~20 ~9 minecraft:snow_block
setblock ~3 ~0 ~-5 minecraft:snow_block
setblock ~4 ~25 ~-3 minecraft:snow_block
setblock ~8 ~19 ~9 minecraft:snow_block
setblock ~-3 ~0 ~-7 minecraft:snow_block
setblock ~-8 ~14 ~13 minecraft:snow_block
setblock ~8 ~17 ~9 minecraft:snow_block
setblock ~8 ~19 ~10 minecraft:snow_block
setblock ~-6 ~4 ~-12 minecraft:snow_block
setblock ~-3 ~9 ~7 minecraft:snow_block
setblock ~-2 ~5 ~4 minecraft:snow_block
setblock ~8 ~6 ~-9 minecraft:snow_block
setblock ~6 ~3 ~2 minecraft:snow_block
setblock ~9 ~7 ~2 minecraft:snow_block
setblock ~8 ~21 ~6 minecraft:snow_block
setblock ~10 ~13 ~-3 minecraft:snow_block
setblock ~8 ~20 ~7 minecraft:snow_block
setblock ~2 ~27 ~3 minecraft:snow_block
setblock ~-5 ~20 ~10 minecraft:snow_block
setblock ~2 ~13 ~18 minecraft:snow_block
setblock ~9 ~22 ~4 minecraft:snow_block
setblock ~-5 ~16 ~-13 minecraft:snow_block
setblock ~5 ~5 ~13 minecraft:snow_block
setblock ~-7 ~11 ~11 minecraft:snow_block
setblock ~8 ~19 ~8 minecraft:snow_block
setblock ~8 ~15 ~9 minecraft:snow_block
setblock ~-5 ~7 ~19 minecraft:snow_block
setblock ~6 ~15 ~-12 minecraft:snow_block
setblock ~8 ~18 ~8 minecraft:snow_block
setblock ~8 ~6 ~-11 minecraft:snow_block
setblock ~-1 ~9 ~21 minecraft:snow_block
setblock ~1 ~27 ~4 minecraft:snow_block
setblock ~-7 ~4 ~16 minecraft:snow_block
setblock ~1 ~11 ~-15 minecraft:snow_block
setblock ~-7 ~9 ~4 minecraft:snow_block
setblock ~8 ~24 ~3 minecraft:snow_block
setblock ~4 ~20 ~9 minecraft:snow_block
